Workbook

Sheet Dashboard
B2: MERCADOLIBRE ($MELI) — REVERSE DCF MODEL
B3: What FCF growth rate is the market currently pricing in?
B4: =TODAY() | C4: Model auto-recalculates when inputs change. Use Data > Refresh All for live price.
B6: KEY MODEL INPUTS | E6: KEY MODEL OUTPUTS
B7: Current Stock Price | C7: ='Reverse DCF'!C7 | E7: Implied FCF Growth Rate | F7: ='Reverse DCF'!C19
B8: Base FCF (FY2024, $M) | C8: ='Reverse DCF'!C8 | E8: Intrinsic Value (Your View) | F8: ='Reverse DCF'!C24
B9: Shares Outstanding (M) | C9: ='Reverse DCF'!C9 | E9: Premium / (Discount) | F9: ='Reverse DCF'!C25
B10: Net Debt ($M) | C10: ='Reverse DCF'!C10 | E10: Enterprise Value ($M) | F10: ='Reverse DCF'!C43
B11: WACC | C11: ='WACC'!C28 | E11: Equity Value ($M) | F11: ='Reverse DCF'!C44
B12: Terminal Growth Rate | C12: ='Reverse DCF'!C15 | E12: PV of Terminal Value (%) | F12: =IF('Reverse DCF'!C43<>0,'Reverse DCF'!C42/'Reverse DCF'!C43,0)
B15: HISTORICAL FCF SUMMARY ($M)
B16: Metric | C16: 2020 | D16: 2021 | E16: 2022 | F16: 2023 | G16: 2024
B17: Revenue | C17: 3969 | D17: 7069 | E17: 10537 | F17: 14474 | G17: 20777
B18: Gross Profit | C18: 1682 | D18: 3015 | E18: 4497 | F18: 6939 | G18: 10530
B19: EBITDA | C19: 274 | D19: 1163 | E19: 1565 | F19: 3468 | G19: 5300
B20: Net Income | C20: -161 | D20: 83 | E20: 482 | F20: 1280 | G20: 2300
B21: Free Cash Flow | C21: 509 | D21: 1242 | E21: 1095 | F21: 2536 | G21: 3800
B27: Model built with Python + openpyxl | Data: Company filings, analyst estimates | Not investment advice

Sheet Reverse DCF
B2: MELI REVERSE DCF MODEL — Implied Growth Rate Analysis
B3: The model solves for the FCF growth rate the market is pricing into the current stock price.
B5: INPUTS & ASSUMPTIONS | H5: REVERSE DCF LOOKUP TABLE
B6: Parameter | C6: Value | E6: Key Output | F6: Value | H6: Each row shows the stock price implied by that growth rate. Market-implied growth = row where Implied Price ≈ Current Price.
B7: Current Stock Price ($) | C7: =IFERROR(INDEX(STOCKHISTORY("MELI",TODAY()-7,TODAY(),0,0),COUNTA(STOCKHISTORY("MELI",TODAY()-7,TODAY(),0,0)),1),1950) | D7: ← Auto-updates via STOCKHISTORY (Excel 365) | E7: ■ IMPLIED GROWTH RATE (Market) | F7: =IFERROR(INDEX($H$8:$H$68,MATCH(MIN(ABS($I$8:$I$68-$C$7)),ABS($I$8:$I$68-$C$7),0)),"#N/A") | H7: Trial FCF Growth | I7: Implied Price ($) | J7: vs Current Price
B8: Base FCF — FY2024 ($M) | C8: 3800 | D8: ← FY2024 actual/estimate; update each year | E8: FCF CAGR 2021–2024 (Historical) | F8: =(C8/1242)^(1/3)-1 | H8: 0 | I8: =IFERROR((SUMPRODUCT($C$8*(1+H8)^ROW(INDIRECT("1:"&$C$15)),(1/(1+$C$13))^ROW(INDIRECT("1:"&$C$15)))+$C$8*(1+H8)^$C$15*(1+$C$14)/($C$13-$C$14)/(1+$C$13)^$C$15-$C$10)/$C$9,"N/A") | J8: =IFERROR((I8-$C$7)/$C$7,"N/A")
B9: Shares Outstanding (M) | C9: 51 | D9: ← Diluted shares including RSUs | E9: ■ INTRINSIC VALUE — Your View | F9: =IFERROR((SUMPRODUCT($C$8*(1+$C$16)^ROW(INDIRECT("1:"&$C$15)),(1/(1+$C$13))^ROW(INDIRECT("1:"&$C$15)))+$C$8*(1+$C$16)^$C$15*(1+$C$14)/($C$13-$C$14)/(1+$C$13)^$C$15-$C$10)/$C$9,"Check WACC>TermG") | H9: 0.01 | I9: =IFERROR((SUMPRODUCT($C$8*(1+H9)^ROW(INDIRECT("1:"&$C$15)),(1/(1+$C$13))^ROW(INDIRECT("1:"&$C$15)))+$C$8*(1+H9)^$C$15*(1+$C$14)/($C$13-$C$14)/(1+$C$13)^$C$15-$C$10)/$C$9,"N/A") | J9: =IFERROR((I9-$C$7)/$C$7,"N/A")
B10: Net Debt ($M) | C10: 2000 | D10: ← Total debt minus cash & equivalents | E10: Premium / (Discount) to Market | F10: =IFERROR((F9-C7)/C7,0) | H10: 0.02 | I10: =IFERROR((SUMPRODUCT($C$8*(1+H10)^ROW(INDIRECT("1:"&$C$15)),(1/(1+$C$13))^ROW(INDIRECT("1:"&$C$15)))+$C$8*(1+H10)^$C$15*(1+$C$14)/($C$13-$C$14)/(1+$C$13)^$C$15-$C$10)/$C$9,"N/A") | J10: =IFERROR((I10-$C$7)/$C$7,"N/A")
E11: EV at Your Target Growth ($M) | F11: =IFERROR(SUMPRODUCT($C$8*(1+$C$16)^ROW(INDIRECT("1:"&$C$15)),(1/(1+$C$13))^ROW(INDIRECT("1:"&$C$15)))+$C$8*(1+$C$16)^$C$15*(1+$C$14)/($C$13-$C$14)/(1+$C$13)^$C$15,"N/A") | H11: 0.03 | I11: =IFERROR((SUMPRODUCT($C$8*(1+H11)^ROW(INDIRECT("1:"&$C$15)),(1/(1+$C$13))^ROW(INDIRECT("1:"&$C$15)))+$C$8*(1+H11)^$C$15*(1+$C$14)/($C$13-$C$14)/(1+$C$13)^$C$15-$C$10)/$C$9,"N/A") | J11: =IFERROR((I11-$C$7)/$C$7,"N/A")
B12: DCF ASSUMPTIONS | H12: 0.04 | I12: =IFERROR((SUMPRODUCT($C$8*(1+H12)^ROW(INDIRECT("1:"&$C$15)),(1/(1+$C$13))^ROW(INDIRECT("1:"&$C$15)))+$C$8*(1+H12)^$C$15*(1+$C$14)/($C$13-$C$14)/(1+$C$13)^$C$15-$C$10)/$C$9,"N/A") | J12: =IFERROR((I12-$C$7)/$C$7,"N/A")
B13: WACC | C13: ='WACC'!C28 | D13: ← From WACC sheet (auto-linked) | H13: 0.05 | I13: =IFERROR((SUMPRODUCT($C$8*(1+H13)^ROW(INDIRECT("1:"&$C$15)),(1/(1+$C$13))^ROW(INDIRECT("1:"&$C$15)))+$C$8*(1+H13)^$C$15*(1+$C$14)/($C$13-$C$14)/(1+$C$13)^$C$15-$C$10)/$C$9,"N/A") | J13: =IFERROR((I13-$C$7)/$C$7,"N/A")
B14: Terminal Growth Rate | C14: 0.04 | D14: ← Long-run FCF growth (4% = LatAm GDP) | H14: 0.06 | I14: =IFERROR((SUMPRODUCT($C$8*(1+H14)^ROW(INDIRECT("1:"&$C$15)),(1/(1+$C$13))^ROW(INDIRECT("1:"&$C$15)))+$C$8*(1+H14)^$C$15*(1+$C$14)/($C$13-$C$14)/(1+$C$13)^$C$15-$C$10)/$C$9,"N/A") | J14: =IFERROR((I14-$C$7)/$C$7,"N/A")
B15: Projection Years | C15: 10 | D15: ← Explicit forecast horizon | H15: 0.07 | I15: =IFERROR((SUMPRODUCT($C$8*(1+H15)^ROW(INDIRECT("1:"&$C$15)),(1/(1+$C$13))^ROW(INDIRECT("1:"&$C$15)))+$C$8*(1+H15)^$C$15*(1+$C$14)/($C$13-$C$14)/(1+$C$13)^$C$15-$C$10)/$C$9,"N/A") | J15: =IFERROR((I15-$C$7)/$C$7,"N/A")
B16: Your Target Growth Rate | C16: 0.25 | D16: ← YOUR assumption → drives Forward DCF | H16: 0.08 | I16: =IFERROR((SUMPRODUCT($C$8*(1+H16)^ROW(INDIRECT("1:"&$C$15)),(1/(1+$C$13))^ROW(INDIRECT("1:"&$C$15)))+$C$8*(1+H16)^$C$15*(1+$C$14)/($C$13-$C$14)/(1+$C$13)^$C$15-$C$10)/$C$9,"N/A") | J16: =IFERROR((I16-$C$7)/$C$7,"N/A")
H17: 0.09 | I17: =IFERROR((SUMPRODUCT($C$8*(1+H17)^ROW(INDIRECT("1:"&$C$15)),(1/(1+$C$13))^ROW(INDIRECT("1:"&$C$15)))+$C$8*(1+H17)^$C$15*(1+$C$14)/($C$13-$C$14)/(1+$C$13)^$C$15-$C$10)/$C$9,"N/A") | J17: =IFERROR((I17-$C$7)/$C$7,"N/A")
H18: 0.1 | I18: =IFERROR((SUMPRODUCT($C$8*(1+H18)^ROW(INDIRECT("1:"&$C$15)),(1/(1+$C$13))^ROW(INDIRECT("1:"&$C$15)))+$C$8*(1+H18)^$C$15*(1+$C$14)/($C$13-$C$14)/(1+$C$13)^$C$15-$C$10)/$C$9,"N/A") | J18: =IFERROR((I18-$C$7)/$C$7,"N/A")
C19: =F7 | H19: 0.11 | I19: =IFERROR((SUMPRODUCT($C$8*(1+H19)^ROW(INDIRECT("1:"&$C$15)),(1/(1+$C$13))^ROW(INDIRECT("1:"&$C$15)))+$C$8*(1+H19)^$C$15*(1+$C$14)/($C$13-$C$14)/(1+$C$13)^$C$15-$C$10)/$C$9,"N/A") | J19: =IFERROR((I19-$C$7)/$C$7,"N/A")
H20: 0.12 | I20: =IFERROR((SUMPRODUCT($C$8*(1+H20)^ROW(INDIRECT("1:"&$C$15)),(1/(1+$C$13))^ROW(INDIRECT("1:"&$C$15)))+$C$8*(1+H20)^$C$15*(1+$C$14)/($C$13-$C$14)/(1+$C$13)^$C$15-$C$10)/$C$9,"N/A") | J20: =IFERROR((I20-$C$7)/$C$7,"N/A")
H21: 0.13 | I21: =IFERROR((SUMPRODUCT($C$8*(1+H21)^ROW(INDIRECT("1:"&$C$15)),(1/(1+$C$13))^ROW(INDIRECT("1:"&$C$15)))+$C$8*(1+H21)^$C$15*(1+$C$14)/($C$13-$C$14)/(1+$C$13)^$C$15-$C$10)/$C$9,"N/A") | J21: =IFERROR((I21-$C$7)/$C$7,"N/A")
H22: 0.14 | I22: =IFERROR((SUMPRODUCT($C$8*(1+H22)^ROW(INDIRECT("1:"&$C$15)),(1/(1+$C$13))^ROW(INDIRECT("1:"&$C$15)))+$C$8*(1+H22)^$C$15*(1+$C$14)/($C$13-$C$14)/(1+$C$13)^$C$15-$C$10)/$C$9,"N/A") | J22: =IFERROR((I22-$C$7)/$C$7,"N/A")
H23: 0.15 | I23: =IFERROR((SUMPRODUCT($C$8*(1+H23)^ROW(INDIRECT("1:"&$C$15)),(1/(1+$C$13))^ROW(INDIRECT("1:"&$C$15)))+$C$8*(1+H23)^$C$15*(1+$C$14)/($C$13-$C$14)/(1+$C$13)^$C$15-$C$10)/$C$9,"N/A") | J23: =IFERROR((I23-$C$7)/$C$7,"N/A")
C24: =F9 | H24: 0.16 | I24: =IFERROR((SUMPRODUCT($C$8*(1+H24)^ROW(INDIRECT("1:"&$C$15)),(1/(1+$C$13))^ROW(INDIRECT("1:"&$C$15)))+$C$8*(1+H24)^$C$15*(1+$C$14)/($C$13-$C$14)/(1+$C$13)^$C$15-$C$10)/$C$9,"N/A") | J24: =IFERROR((I24-$C$7)/$C$7,"N/A")
C25: =F10 | H25: 0.17 | I25: =IFERROR((SUMPRODUCT($C$8*(1+H25)^ROW(INDIRECT("1:"&$C$15)),(1/(1+$C$13))^ROW(INDIRECT("1:"&$C$15)))+$C$8*(1+H25)^$C$15*(1+$C$14)/($C$13-$C$14)/(1+$C$13)^$C$15-$C$10)/$C$9,"N/A") | J25: =IFERROR((I25-$C$7)/$C$7,"N/A")
H26: 0.18 | I26: =IFERROR((SUMPRODUCT($C$8*(1+H26)^ROW(INDIRECT("1:"&$C$15)),(1/(1+$C$13))^ROW(INDIRECT("1:"&$C$15)))+$C$8*(1+H26)^$C$15*(1+$C$14)/($C$13-$C$14)/(1+$C$13)^$C$15-$C$10)/$C$9,"N/A") | J26: =IFERROR((I26-$C$7)/$C$7,"N/A")
H27: 0.19 | I27: =IFERROR((SUMPRODUCT($C$8*(1+H27)^ROW(INDIRECT("1:"&$C$15)),(1/(1+$C$13))^ROW(INDIRECT("1:"&$C$15)))+$C$8*(1+H27)^$C$15*(1+$C$14)/($C$13-$C$14)/(1+$C$13)^$C$15-$C$10)/$C$9,"N/A") | J27: =IFERROR((I27-$C$7)/$C$7,"N/A")
B28: FCF PROJECTION — At Market-Implied Growth Rate | H28: 0.2 | I28: =IFERROR((SUMPRODUCT($C$8*(1+H28)^ROW(INDIRECT("1:"&$C$15)),(1/(1+$C$13))^ROW(INDIRECT("1:"&$C$15)))+$C$8*(1+H28)^$C$15*(1+$C$14)/($C$13-$C$14)/(1+$C$13)^$C$15-$C$10)/$C$9,"N/A") | J28: =IFERROR((I28-$C$7)/$C$7,"N/A")
B29: Year | C29: Calendar | D29: FCF ($M) | E29: YoY Growth | F29: PV Factor | G29: PV of FCF ($M) | H29: 0.21 | I29: =IFERROR((SUMPRODUCT($C$8*(1+H29)^ROW(INDIRECT("1:"&$C$15)),(1/(1+$C$13))^ROW(INDIRECT("1:"&$C$15)))+$C$8*(1+H29)^$C$15*(1+$C$14)/($C$13-$C$14)/(1+$C$13)^$C$15-$C$10)/$C$9,"N/A") | J29: =IFERROR((I29-$C$7)/$C$7,"N/A")
B30: Year 1 | C30: =2024+1 | D30: =$C$8*(1+$F$7)^1 | E30: =$F$7 | F30: =1/(1+$C$13)^1 | G30: =D30*F30 | H30: 0.22 | I30: =IFERROR((SUMPRODUCT($C$8*(1+H30)^ROW(INDIRECT("1:"&$C$15)),(1/(1+$C$13))^ROW(INDIRECT("1:"&$C$15)))+$C$8*(1+H30)^$C$15*(1+$C$14)/($C$13-$C$14)/(1+$C$13)^$C$15-$C$10)/$C$9,"N/A") | J30: =IFERROR((I30-$C$7)/$C$7,"N/A")
B31: Year 2 | C31: =2024+2 | D31: =$C$8*(1+$F$7)^2 | E31: =$F$7 | F31: =1/(1+$C$13)^2 | G31: =D31*F31 | H31: 0.23 | I31: =IFERROR((SUMPRODUCT($C$8*(1+H31)^ROW(INDIRECT("1:"&$C$15)),(1/(1+$C$13))^ROW(INDIRECT("1:"&$C$15)))+$C$8*(1+H31)^$C$15*(1+$C$14)/($C$13-$C$14)/(1+$C$13)^$C$15-$C$10)/$C$9,"N/A") | J31: =IFERROR((I31-$C$7)/$C$7,"N/A")
B32: Year 3 | C32: =2024+3 | D32: =$C$8*(1+$F$7)^3 | E32: =$F$7 | F32: =1/(1+$C$13)^3 | G32: =D32*F32 | H32: 0.24 | I32: =IFERROR((SUMPRODUCT($C$8*(1+H32)^ROW(INDIRECT("1:"&$C$15)),(1/(1+$C$13))^ROW(INDIRECT("1:"&$C$15)))+$C$8*(1+H32)^$C$15*(1+$C$14)/($C$13-$C$14)/(1+$C$13)^$C$15-$C$10)/$C$9,"N/A") | J32: =IFERROR((I32-$C$7)/$C$7,"N/A")
B33: Year 4 | C33: =2024+4 | D33: =$C$8*(1+$F$7)^4 | E33: =$F$7 | F33: =1/(1+$C$13)^4 | G33: =D33*F33 | H33: 0.25 | I33: =IFERROR((SUMPRODUCT($C$8*(1+H33)^ROW(INDIRECT("1:"&$C$15)),(1/(1+$C$13))^ROW(INDIRECT("1:"&$C$15)))+$C$8*(1+H33)^$C$15*(1+$C$14)/($C$13-$C$14)/(1+$C$13)^$C$15-$C$10)/$C$9,"N/A") | J33: =IFERROR((I33-$C$7)/$C$7,"N/A")
B34: Year 5 | C34: =2024+5 | D34: =$C$8*(1+$F$7)^5 | E34: =$F$7 | F34: =1/(1+$C$13)^5 | G34: =D34*F34 | H34: 0.26 | I34: =IFERROR((SUMPRODUCT($C$8*(1+H34)^ROW(INDIRECT("1:"&$C$15)),(1/(1+$C$13))^ROW(INDIRECT("1:"&$C$15)))+$C$8*(1+H34)^$C$15*(1+$C$14)/($C$13-$C$14)/(1+$C$13)^$C$15-$C$10)/$C$9,"N/A") | J34: =IFERROR((I34-$C$7)/$C$7,"N/A")
B35: Year 6 | C35: =2024+6 | D35: =$C$8*(1+$F$7)^6 | E35: =$F$7 | F35: =1/(1+$C$13)^6 | G35: =D35*F35 | H35: 0.27 | I35: =IFERROR((SUMPRODUCT($C$8*(1+H35)^ROW(INDIRECT("1:"&$C$15)),(1/(1+$C$13))^ROW(INDIRECT("1:"&$C$15)))+$C$8*(1+H35)^$C$15*(1+$C$14)/($C$13-$C$14)/(1+$C$13)^$C$15-$C$10)/$C$9,"N/A") | J35: =IFERROR((I35-$C$7)/$C$7,"N/A")
B36: Year 7 | C36: =2024+7 | D36: =$C$8*(1+$F$7)^7 | E36: =$F$7 | F36: =1/(1+$C$13)^7 | G36: =D36*F36 | H36: 0.28 | I36: =IFERROR((SUMPRODUCT($C$8*(1+H36)^ROW(INDIRECT("1:"&$C$15)),(1/(1+$C$13))^ROW(INDIRECT("1:"&$C$15)))+$C$8*(1+H36)^$C$15*(1+$C$14)/($C$13-$C$14)/(1+$C$13)^$C$15-$C$10)/$C$9,"N/A") | J36: =IFERROR((I36-$C$7)/$C$7,"N/A")
B37: Year 8 | C37: =2024+8 | D37: =$C$8*(1+$F$7)^8 | E37: =$F$7 | F37: =1/(1+$C$13)^8 | G37: =D37*F37 | H37: 0.29 | I37: =IFERROR((SUMPRODUCT($C$8*(1+H37)^ROW(INDIRECT("1:"&$C$15)),(1/(1+$C$13))^ROW(INDIRECT("1:"&$C$15)))+$C$8*(1+H37)^$C$15*(1+$C$14)/($C$13-$C$14)/(1+$C$13)^$C$15-$C$10)/$C$9,"N/A") | J37: =IFERROR((I37-$C$7)/$C$7,"N/A")
B38: Year 9 | C38: =2024+9 | D38: =$C$8*(1+$F$7)^9 | E38: =$F$7 | F38: =1/(1+$C$13)^9 | G38: =D38*F38 | H38: 0.3 | I38: =IFERROR((SUMPRODUCT($C$8*(1+H38)^ROW(INDIRECT("1:"&$C$15)),(1/(1+$C$13))^ROW(INDIRECT("1:"&$C$15)))+$C$8*(1+H38)^$C$15*(1+$C$14)/($C$13-$C$14)/(1+$C$13)^$C$15-$C$10)/$C$9,"N/A") | J38: =IFERROR((I38-$C$7)/$C$7,"N/A")
B39: Year 10 | C39: =2024+10 | D39: =$C$8*(1+$F$7)^10 | E39: =$F$7 | F39: =1/(1+$C$13)^10 | G39: =D39*F39 | H39: 0.31 | I39: =IFERROR((SUMPRODUCT($C$8*(1+H39)^ROW(INDIRECT("1:"&$C$15)),(1/(1+$C$13))^ROW(INDIRECT("1:"&$C$15)))+$C$8*(1+H39)^$C$15*(1+$C$14)/($C$13-$C$14)/(1+$C$13)^$C$15-$C$10)/$C$9,"N/A") | J39: =IFERROR((I39-$C$7)/$C$7,"N/A")
H40: 0.32 | I40: =IFERROR((SUMPRODUCT($C$8*(1+H40)^ROW(INDIRECT("1:"&$C$15)),(1/(1+$C$13))^ROW(INDIRECT("1:"&$C$15)))+$C$8*(1+H40)^$C$15*(1+$C$14)/($C$13-$C$14)/(1+$C$13)^$C$15-$C$10)/$C$9,"N/A") | J40: =IFERROR((I40-$C$7)/$C$7,"N/A")
B41: Sum of PV of FCFs ($M) | C41: =SUM(G30:G39) | H41: 0.33 | I41: =IFERROR((SUMPRODUCT($C$8*(1+H41)^ROW(INDIRECT("1:"&$C$15)),(1/(1+$C$13))^ROW(INDIRECT("1:"&$C$15)))+$C$8*(1+H41)^$C$15*(1+$C$14)/($C$13-$C$14)/(1+$C$13)^$C$15-$C$10)/$C$9,"N/A") | J41: =IFERROR((I41-$C$7)/$C$7,"N/A")
B42: Terminal Value — Undiscounted ($M) | C42: =IFERROR($C$8*(1+$F$7)^$C$15*(1+$C$14)/($C$13-$C$14),"Check WACC>TermG") | H42: 0.34 | I42: =IFERROR((SUMPRODUCT($C$8*(1+H42)^ROW(INDIRECT("1:"&$C$15)),(1/(1+$C$13))^ROW(INDIRECT("1:"&$C$15)))+$C$8*(1+H42)^$C$15*(1+$C$14)/($C$13-$C$14)/(1+$C$13)^$C$15-$C$10)/$C$9,"N/A") | J42: =IFERROR((I42-$C$7)/$C$7,"N/A")
...

Sheet WACC
B2: WACC — WEIGHTED AVERAGE COST OF CAPITAL
B3: MercadoLibre, Inc. | Ticker: MELI | Exchange: NASDAQ
B5: COST OF EQUITY (CAPM)
B6: Component | C6: Value | D6: Notes
B7: Risk-Free Rate (10Y UST) | C7: 0.045 | D7: US 10-Year Treasury yield
B8: Equity Beta | C8: 1.35 | D8: 5-yr monthly regression vs S&P 500
B9: Equity Risk Premium (ERP) | C9: 0.055 | D9: Damodaran implied ERP
B10: Country Risk Premium (LatAm) | C10: 0.015 | D10: Weighted avg of MELI operating markets
B11: Cost of Equity = Rf + β × (ERP + CRP) | C11: =C7+C8*(C9+C10) | D11: CAPM formula
B14: COST OF DEBT
B15: Pre-Tax Cost of Debt | C15: 0.065 | D15: Blended yield on MELI bonds
B16: Effective Tax Rate | C16: 0.3 | D16: Blended across LatAm jurisdictions
B17: After-Tax Cost of Debt = Kd × (1 – Tax) | C17: =C15*(1-C16) | D17: Tax shield on interest
B20: CAPITAL STRUCTURE
B21: Market Capitalisation ($M) | C21: 97000 | D21: Price × Shares outstanding
B22: Total Debt ($M) | C22: 7000 | D22: Long-term + short-term debt
B23: Total Capital ($M) | C23: =C21+C22
B24: Equity Weight (E/V) | C24: =C21/C23
B25: Debt Weight (D/V) | C25: =C22/C23
B28: WACC = (E/V) × Ke + (D/V) × Kd(1–t) | C28: =C24*C11+C25*C17 | D28: ← WACC used in Reverse DCF model
B30: Note: Update Market Cap cell (C21) when stock price changes for accurate weights.

Sheet Historicals
B2: MERCADOLIBRE — HISTORICAL FINANCIALS ($M unless noted)
B3: Source: MercadoLibre SEC filings & company guidance. FY2024 = analyst consensus estimate.
B5: Metric | C5: 2020 | D5: 2021 | E5: 2022 | F5: 2023 | G5: 2024 | H5: CAGR '20–'24
B6: INCOME STATEMENT
B7: Revenue | C7: 3969 | D7: 7069 | E7: 10537 | F7: 14474 | G7: 20777 | H7: =IFERROR((G7/C7)^(1/4)-1,"")
B8: Gross Profit | C8: 1682 | D8: 3015 | E8: 4497 | F8: 6939 | G8: 10530 | H8: =IFERROR((G8/C8)^(1/4)-1,"")
B9: Gross Margin | C9: =IF(C7<>0,C8/C7,0) | D9: =IF(D7<>0,D8/D7,0) | E9: =IF(E7<>0,E8/E7,0) | F9: =IF(F7<>0,F8/F7,0) | G9: =IF(G7<>0,G8/G7,0) | H9: —
B10: EBITDA | C10: 274 | D10: 1163 | E10: 1565 | F10: 3468 | G10: 5300 | H10: =IFERROR((G10/C10)^(1/4)-1,"")
B11: EBITDA Margin | C11: =IF(C7<>0,C10/C7,0) | D11: =IF(D7<>0,D10/D7,0) | E11: =IF(E7<>0,E10/E7,0) | F11: =IF(F7<>0,F10/F7,0) | G11: =IF(G7<>0,G10/G7,0) | H11: —
B12: Net Income | C12: -161 | D12: 83 | E12: 482 | F12: 1280 | G12: 2300 | H12: =IFERROR((G12/C12)^(1/4)-1,"")
B13: CASH FLOW
B14: Operating Cash Flow | C14: 722 | D14: 1571 | E14: 1644 | F14: 3164 | G14: 4500 | H14: =IFERROR((G14/C14)^(1/4)-1,"")
B15: Capital Expenditures | C15: 213 | D15: 329 | E15: 549 | F15: 628 | G15: 700 | H15: =IFERROR((G15/C15)^(1/4)-1,"")
B16: Free Cash Flow | C16: 509 | D16: 1242 | E16: 1095 | F16: 2536 | G16: 3800 | H16: =IFERROR((G16/C16)^(1/4)-1,"")
B17: FCF Margin | C17: =IF(C7<>0,C16/C7,0) | D17: =IF(D7<>0,D16/D7,0) | E17: =IF(E7<>0,E16/E7,0) | F17: =IF(F7<>0,F16/F7,0) | G17: =IF(G7<>0,G16/G7,0) | H17: —
B18: FCF Growth YoY | D18: =IF(C16<>0,D16/C16-1,0) | E18: =IF(D16<>0,E16/D16-1,0) | F18: =IF(E16<>0,F16/E16-1,0) | G18: =IF(F16<>0,G16/F16-1,0) | H18: —

Sheet Sensitivity
B2: SENSITIVITY ANALYSIS — DCF Implied Stock Price ($)
B3: Each cell shows the implied stock price for a given combination of WACC (rows) and FCF Growth Rate (columns). Shading: green = above current price.
B4: Current Stock Price → | C4: ='Reverse DCF'!C7 | D4: ← Reference for color-coding below
B6: IMPLIED STOCK PRICE ($ / share)
B7: WACC ↓ / Growth → | C7: 10% | D7: 15% | E7: 20% | F7: 25% | G7: 30% | H7: 35% | I7: 40% | J7: 45% | K7: 50% | L7: 55%
B8: 8% | C8: =IFERROR((SUMPRODUCT('Reverse DCF'!$C$8*(1+C$7)^ROW(INDIRECT("1:"&'Reverse DCF'!$C$15)),(1/(1+$B8))^ROW(INDIRECT("1:"&'Reverse DCF'!$C$15)))+'Reverse DCF'!$C$8*(1+C$7)^'Reverse DCF'!$C$15*(1+'Reverse DCF'!$C$14)/($B8-'Reverse DCF'!$C$14)/(1+$B8)^'Reverse DCF'!$C$15-'Reverse DCF'!$C$10)/'Reverse DCF'!$C$9,"N/A") | D8: =IFERROR((SUMPRODUCT('Reverse DCF'!$C$8*(1+D$7)^ROW(INDIRECT("1:"&'Reverse DCF'!$C$15)),(1/(1+$B8))^ROW(INDIRECT("1:"&'Reverse DCF'!$C$15)))+'Reverse DCF'!$C$8*(1+D$7)^'Reverse DCF'!$C$15*(1+'Reverse DCF'!$C$14)/($B8-'Reverse DCF'!$C$14)/(1+$B8)^'Reverse DCF'!$C$15-'Reverse DCF'!$C$10)/'Reverse DCF'!$C$9,"N/A") | E8: =IFERROR((SUMPRODUCT('Reverse DCF'!$C$8*(1+E$7)^ROW(INDIRECT("1:"&'Reverse DCF'!$C$15)),(1/(1+$B8))^ROW(INDIRECT("1:"&'Reverse DCF'!$C$15)))+'Reverse DCF'!$C$8*(1+E$7)^'Reverse DCF'!$C$15*(1+'Reverse DCF'!$C$14)/($B8-'Reverse DCF'!$C$14)/(1+$B8)^'Reverse DCF'!$C$15-'Reverse DCF'!$C$10)/'Reverse DCF'!$C$9,"N/A") | F8: =IFERROR((SUMPRODUCT('Reverse DCF'!$C$8*(1+F$7)^ROW(INDIRECT("1:"&'Reverse DCF'!$C$15)),(1/(1+$B8))^ROW(INDIRECT("1:"&'Reverse DCF'!$C$15)))+'Reverse DCF'!$C$8*(1+F$7)^'Reverse DCF'!$C$15*(1+'Reverse DCF'!$C$14)/($B8-'Reverse DCF'!$C$14)/(1+$B8)^'Reverse DCF'!$C$15-'Reverse DCF'!$C$10)/'Reverse DCF'!$C$9,"N/A") | G8: =IFERROR((SUMPRODUCT('Reverse DCF'!$C$8*(1+G$7)^ROW(INDIRECT("1:"&'Reverse DCF'!$C$15)),(1/(1+$B8))^ROW(INDIRECT("1:"&'Reverse DCF'!$C$15)))+'Reverse DCF'!$C$8*(1+G$7)^'Reverse DCF'!$C$15*(1+'Reverse DCF'!$C$14)/($B8-'Reverse DCF'!$C$14)/(1+$B8)^'Reverse DCF'!$C$15-'Reverse DCF'!$C$10)/'Reverse DCF'!$C$9,"N/A") | H8: =IFERROR((SUMPRODUCT('Reverse DCF'!$C$8*(1+H$7)^ROW(INDIRECT("1:"&'Reverse DCF'!$C$15)),(1/(1+$B8))^ROW(INDIRECT("1:"&'Reverse DCF'!$C$15)))+'Reverse DCF'!$C$8*(1+H$7)^'Reverse DCF'!$C$15*(1+'Reverse DCF'!$C$14)/($B8-'Reverse DCF'!$C$14)/(1+$B8)^'Reverse DCF'!$C$15-'Reverse DCF'!$C$10)/'Reverse DCF'!$C$9,"N/A") | I8: =IFERROR((SUMPRODUCT('Reverse DCF'!$C$8*(1+I$7)^ROW(INDIRECT("1:"&'Reverse DCF'!$C$15)),(1/(1+$B8))^ROW(INDIRECT("1:"&'Reverse DCF'!$C$15)))+'Reverse DCF'!$C$8*(1+I$7)^'Reverse DCF'!$C$15*(1+'Reverse DCF'!$C$14)/($B8-'Reverse DCF'!$C$14)/(1+$B8)^'Reverse DCF'!$C$15-'Reverse DCF'!$C$10)/'Reverse DCF'!$C$9,"N/A") | J8: =IFERROR((SUMPRODUCT('Reverse DCF'!$C$8*(1+J$7)^ROW(INDIRECT("1:"&'Reverse DCF'!$C$15)),(1/(1+$B8))^ROW(INDIRECT("1:"&'Reverse DCF'!$C$15)))+'Reverse DCF'!$C$8*(1+J$7)^'Reverse DCF'!$C$15*(1+'Reverse DCF'!$C$14)/($B8-'Reverse DCF'!$C$14)/(1+$B8)^'Reverse DCF'!$C$15-'Reverse DCF'!$C$10)/'Reverse DCF'!$C$9,"N/A") | ... L8: =IFERROR((SUMPRODUCT('Reverse DCF'!$C$8*(1+L$7)^ROW(INDIRECT("1:"&'Reverse DCF'!$C$15)),(1/(1+$B8))^ROW(INDIRECT("1:"&'Reverse DCF'!$C$15)))+'Reverse DCF'!$C$8*(1+L$7)^'Reverse DCF'!$C$15*(1+'Reverse DCF'!$C$14)/($B8-'Reverse DCF'!$C$14)/(1+$B8)^'Reverse DCF'!$C$15-'Reverse DCF'!$C$10)/'Reverse DCF'!$C$9,"N/A")
B9: 9% | C9: =IFERROR((SUMPRODUCT('Reverse DCF'!$C$8*(1+C$7)^ROW(INDIRECT("1:"&'Reverse DCF'!$C$15)),(1/(1+$B9))^ROW(INDIRECT("1:"&'Reverse DCF'!$C$15)))+'Reverse DCF'!$C$8*(1+C$7)^'Reverse DCF'!$C$15*(1+'Reverse DCF'!$C$14)/($B9-'Reverse DCF'!$C$14)/(1+$B9)^'Reverse DCF'!$C$15-'Reverse DCF'!$C$10)/'Reverse DCF'!$C$9,"N/A") | D9: =IFERROR((SUMPRODUCT('Reverse DCF'!$C$8*(1+D$7)^ROW(INDIRECT("1:"&'Reverse DCF'!$C$15)),(1/(1+$B9))^ROW(INDIRECT("1:"&'Reverse DCF'!$C$15)))+'Reverse DCF'!$C$8*(1+D$7)^'Reverse DCF'!$C$15*(1+'Reverse DCF'!$C$14)/($B9-'Reverse DCF'!$C$14)/(1+$B9)^'Reverse DCF'!$C$15-'Reverse DCF'!$C$10)/'Reverse DCF'!$C$9,"N/A") | E9: =IFERROR((SUMPRODUCT('Reverse DCF'!$C$8*(1+E$7)^ROW(INDIRECT("1:"&'Reverse DCF'!$C$15)),(1/(1+$B9))^ROW(INDIRECT("1:"&'Reverse DCF'!$C$15)))+'Reverse DCF'!$C$8*(1+E$7)^'Reverse DCF'!$C$15*(1+'Reverse DCF'!$C$14)/($B9-'Reverse DCF'!$C$14)/(1+$B9)^'Reverse DCF'!$C$15-'Reverse DCF'!$C$10)/'Reverse DCF'!$C$9,"N/A") | F9: =IFERROR((SUMPRODUCT('Reverse DCF'!$C$8*(1+F$7)^ROW(INDIRECT("1:"&'Reverse DCF'!$C$15)),(1/(1+$B9))^ROW(INDIRECT("1:"&'Reverse DCF'!$C$15)))+'Reverse DCF'!$C$8*(1+F$7)^'Reverse DCF'!$C$15*(1+'Reverse DCF'!$C$14)/($B9-'Reverse DCF'!$C$14)/(1+$B9)^'Reverse DCF'!$C$15-'Reverse DCF'!$C$10)/'Reverse DCF'!$C$9,"N/A") | G9: =IFERROR((SUMPRODUCT('Reverse DCF'!$C$8*(1+G$7)^ROW(INDIRECT("1:"&'Reverse DCF'!$C$15)),(1/(1+$B9))^ROW(INDIRECT("1:"&'Reverse DCF'!$C$15)))+'Reverse DCF'!$C$8*(1+G$7)^'Reverse DCF'!$C$15*(1+'Reverse DCF'!$C$14)/($B9-'Reverse DCF'!$C$14)/(1+$B9)^'Reverse DCF'!$C$15-'Reverse DCF'!$C$10)/'Reverse DCF'!$C$9,"N/A") | H9: =IFERROR((SUMPRODUCT('Reverse DCF'!$C$8*(1+H$7)^ROW(INDIRECT("1:"&'Reverse DCF'!$C$15)),(1/(1+$B9))^ROW(INDIRECT("1:"&'Reverse DCF'!$C$15)))+'Reverse DCF'!$C$8*(1+H$7)^'Reverse DCF'!$C$15*(1+'Reverse DCF'!$C$14)/($B9-'Reverse DCF'!$C$14)/(1+$B9)^'Reverse DCF'!$C$15-'Reverse DCF'!$C$10)/'Reverse DCF'!$C$9,"N/A") | I9: =IFERROR((SUMPRODUCT('Reverse DCF'!$C$8*(1+I$7)^ROW(INDIRECT("1:"&'Reverse DCF'!$C$15)),(1/(1+$B9))^ROW(INDIRECT("1:"&'Reverse DCF'!$C$15)))+'Reverse DCF'!$C$8*(1+I$7)^'Reverse DCF'!$C$15*(1+'Reverse DCF'!$C$14)/($B9-'Reverse DCF'!$C$14)/(1+$B9)^'Reverse DCF'!$C$15-'Reverse DCF'!$C$10)/'Reverse DCF'!$C$9,"N/A") | J9: =IFERROR((SUMPRODUCT('Reverse DCF'!$C$8*(1+J$7)^ROW(INDIRECT("1:"&'Reverse DCF'!$C$15)),(1/(1+$B9))^ROW(INDIRECT("1:"&'Reverse DCF'!$C$15)))+'Reverse DCF'!$C$8*(1+J$7)^'Reverse DCF'!$C$15*(1+'Reverse DCF'!$C$14)/($B9-'Reverse DCF'!$C$14)/(1+$B9)^'Reverse DCF'!$C$15-'Reverse DCF'!$C$10)/'Reverse DCF'!$C$9,"N/A") | ... L9: =IFERROR((SUMPRODUCT('Reverse DCF'!$C$8*(1+L$7)^ROW(INDIRECT("1:"&'Reverse DCF'!$C$15)),(1/(1+$B9))^ROW(INDIRECT("1:"&'Reverse DCF'!$C$15)))+'Reverse DCF'!$C$8*(1+L$7)^'Reverse DCF'!$C$15*(1+'Reverse DCF'!$C$14)/($B9-'Reverse DCF'!$C$14)/(1+$B9)^'Reverse DCF'!$C$15-'Reverse DCF'!$C$10)/'Reverse DCF'!$C$9,"N/A")
B10: 10% | C10: =IFERROR((SUMPRODUCT('Reverse DCF'!$C$8*(1+C$7)^ROW(INDIRECT("1:"&'Reverse DCF'!$C$15)),(1/(1+$B10))^ROW(INDIRECT("1:"&'Reverse DCF'!$C$15)))+'Reverse DCF'!$C$8*(1+C$7)^'Reverse DCF'!$C$15*(1+'Reverse DCF'!$C$14)/($B10-'Reverse DCF'!$C$14)/(1+$B10)^'Reverse DCF'!$C$15-'Reverse DCF'!$C$10)/'Reverse DCF'!$C$9,"N/A") | D10: =IFERROR((SUMPRODUCT('Reverse DCF'!$C$8*(1+D$7)^ROW(INDIRECT("1:"&'Reverse DCF'!$C$15)),(1/(1+$B10))^ROW(INDIRECT("1:"&'Reverse DCF'!$C$15)))+'Reverse DCF'!$C$8*(1+D$7)^'Reverse DCF'!$C$15*(1+'Reverse DCF'!$C$14)/($B10-'Reverse DCF'!$C$14)/(1+$B10)^'Reverse DCF'!$C$15-'Reverse DCF'!$C$10)/'Reverse DCF'!$C$9,"N/A") | E10: =IFERROR((SUMPRODUCT('Reverse DCF'!$C$8*(1+E$7)^ROW(INDIRECT("1:"&'Reverse DCF'!$C$15)),(1/(1+$B10))^ROW(INDIRECT("1:"&'Reverse DCF'!$C$15)))+'Reverse DCF'!$C$8*(1+E$7)^'Reverse DCF'!$C$15*(1+'Reverse DCF'!$C$14)/($B10-'Reverse DCF'!$C$14)/(1+$B10)^'Reverse DCF'!$C$15-'Reverse DCF'!$C$10)/'Reverse DCF'!$C$9,"N/A") | F10: =IFERROR((SUMPRODUCT('Reverse DCF'!$C$8*(1+F$7)^ROW(INDIRECT("1:"&'Reverse DCF'!$C$15)),(1/(1+$B10))^ROW(INDIRECT("1:"&'Reverse DCF'!$C$15)))+'Reverse DCF'!$C$8*(1+F$7)^'Reverse DCF'!$C$15*(1+'Reverse DCF'!$C$14)/($B10-'Reverse DCF'!$C$14)/(1+$B10)^'Reverse DCF'!$C$15-'Reverse DCF'!$C$10)/'Reverse DCF'!$C$9,"N/A") | G10: =IFERROR((SUMPRODUCT('Reverse DCF'!$C$8*(1+G$7)^ROW(INDIRECT("1:"&'Reverse DCF'!$C$15)),(1/(1+$B10))^ROW(INDIRECT("1:"&'Reverse DCF'!$C$15)))+'Reverse DCF'!$C$8*(1+G$7)^'Reverse DCF'!$C$15*(1+'Reverse DCF'!$C$14)/($B10-'Reverse DCF'!$C$14)/(1+$B10)^'Reverse DCF'!$C$15-'Reverse DCF'!$C$10)/'Reverse DCF'!$C$9,"N/A") | H10: =IFERROR((SUMPRODUCT('Reverse DCF'!$C$8*(1+H$7)^ROW(INDIRECT("1:"&'Reverse DCF'!$C$15)),(1/(1+$B10))^ROW(INDIRECT("1:"&'Reverse DCF'!$C$15)))+'Reverse DCF'!$C$8*(1+H$7)^'Reverse DCF'!$C$15*(1+'Reverse DCF'!$C$14)/($B10-'Reverse DCF'!$C$14)/(1+$B10)^'Reverse DCF'!$C$15-'Reverse DCF'!$C$10)/'Reverse DCF'!$C$9,"N/A") | I10: =IFERROR((SUMPRODUCT('Reverse DCF'!$C$8*(1+I$7)^ROW(INDIRECT("1:"&'Reverse DCF'!$C$15)),(1/(1+$B10))^ROW(INDIRECT("1:"&'Reverse DCF'!$C$15)))+'Reverse DCF'!$C$8*(1+I$7)^'Reverse DCF'!$C$15*(1+'Reverse DCF'!$C$14)/($B10-'Reverse DCF'!$C$14)/(1+$B10)^'Reverse DCF'!$C$15-'Reverse DCF'!$C$10)/'Reverse DCF'!$C$9,"N/A") | J10: =IFERROR((SUMPRODUCT('Reverse DCF'!$C$8*(1+J$7)^ROW(INDIRECT("1:"&'Reverse DCF'!$C$15)),(1/(1+$B10))^ROW(INDIRECT("1:"&'Reverse DCF'!$C$15)))+'Reverse DCF'!$C$8*(1+J$7)^'Reverse DCF'!$C$15*(1+'Reverse DCF'!$C$14)/($B10-'Reverse DCF'!$C$14)/(1+$B10)^'Reverse DCF'!$C$15-'Reverse DCF'!$C$10)/'Reverse DCF'!$C$9,"N/A") | ... L10: =IFERROR((SUMPRODUCT('Reverse DCF'!$C$8*(1+L$7)^ROW(INDIRECT("1:"&'Reverse DCF'!$C$15)),(1/(1+$B10))^ROW(INDIRECT("1:"&'Reverse DCF'!$C$15)))+'Reverse DCF'!$C$8*(1+L$7)^'Reverse DCF'!$C$15*(1+'Reverse DCF'!$C$14)/($B10-'Reverse DCF'!$C$14)/(1+$B10)^'Reverse DCF'!$C$15-'Reverse DCF'!$C$10)/'Reverse DCF'!$C$9,"N/A")
B11: 11% | C11: =IFERROR((SUMPRODUCT('Reverse DCF'!$C$8*(1+C$7)^ROW(INDIRECT("1:"&'Reverse DCF'!$C$15)),(1/(1+$B11))^ROW(INDIRECT("1:"&'Reverse DCF'!$C$15)))+'Reverse DCF'!$C$8*(1+C$7)^'Reverse DCF'!$C$15*(1+'Reverse DCF'!$C$14)/($B11-'Reverse DCF'!$C$14)/(1+$B11)^'Reverse DCF'!$C$15-'Reverse DCF'!$C$10)/'Reverse DCF'!$C$9,"N/A") | D11: =IFERROR((SUMPRODUCT('Reverse DCF'!$C$8*(1+D$7)^ROW(INDIRECT("1:"&'Reverse DCF'!$C$15)),(1/(1+$B11))^ROW(INDIRECT("1:"&'Reverse DCF'!$C$15)))+'Reverse DCF'!$C$8*(1+D$7)^'Reverse DCF'!$C$15*(1+'Reverse DCF'!$C$14)/($B11-'Reverse DCF'!$C$14)/(1+$B11)^'Reverse DCF'!$C$15-'Reverse DCF'!$C$10)/'Reverse DCF'!$C$9,"N/A") | E11: =IFERROR((SUMPRODUCT('Reverse DCF'!$C$8*(1+E$7)^ROW(INDIRECT("1:"&'Reverse DCF'!$C$15)),(1/(1+$B11))^ROW(INDIRECT("1:"&'Reverse DCF'!$C$15)))+'Reverse DCF'!$C$8*(1+E$7)^'Reverse DCF'!$C$15*(1+'Reverse DCF'!$C$14)/($B11-'Reverse DCF'!$C$14)/(1+$B11)^'Reverse DCF'!$C$15-'Reverse DCF'!$C$10)/'Reverse DCF'!$C$9,"N/A") | F11: =IFERROR((SUMPRODUCT('Reverse DCF'!$C$8*(1+F$7)^ROW(INDIRECT("1:"&'Reverse DCF'!$C$15)),(1/(1+$B11))^ROW(INDIRECT("1:"&'Reverse DCF'!$C$15)))+'Reverse DCF'!$C$8*(1+F$7)^'Reverse DCF'!$C$15*(1+'Reverse DCF'!$C$14)/($B11-'Reverse DCF'!$C$14)/(1+$B11)^'Reverse DCF'!$C$15-'Reverse DCF'!$C$10)/'Reverse DCF'!$C$9,"N/A") | G11: =IFERROR((SUMPRODUCT('Reverse DCF'!$C$8*(1+G$7)^ROW(INDIRECT("1:"&'Reverse DCF'!$C$15)),(1/(1+$B11))^ROW(INDIRECT("1:"&'Reverse DCF'!$C$15)))+'Reverse DCF'!$C$8*(1+G$7)^'Reverse DCF'!$C$15*(1+'Reverse DCF'!$C$14)/($B11-'Reverse DCF'!$C$14)/(1+$B11)^'Reverse DCF'!$C$15-'Reverse DCF'!$C$10)/'Reverse DCF'!$C$9,"N/A") | H11: =IFERROR((SUMPRODUCT('Reverse DCF'!$C$8*(1+H$7)^ROW(INDIRECT("1:"&'Reverse DCF'!$C$15)),(1/(1+$B11))^ROW(INDIRECT("1:"&'Reverse DCF'!$C$15)))+'Reverse DCF'!$C$8*(1+H$7)^'Reverse DCF'!$C$15*(1+'Reverse DCF'!$C$14)/($B11-'Reverse DCF'!$C$14)/(1+$B11)^'Reverse DCF'!$C$15-'Reverse DCF'!$C$10)/'Reverse DCF'!$C$9,"N/A") | I11: =IFERROR((SUMPRODUCT('Reverse DCF'!$C$8*(1+I$7)^ROW(INDIRECT("1:"&'Reverse DCF'!$C$15)),(1/(1+$B11))^ROW(INDIRECT("1:"&'Reverse DCF'!$C$15)))+'Reverse DCF'!$C$8*(1+I$7)^'Reverse DCF'!$C$15*(1+'Reverse DCF'!$C$14)/($B11-'Reverse DCF'!$C$14)/(1+$B11)^'Reverse DCF'!$C$15-'Reverse DCF'!$C$10)/'Reverse DCF'!$C$9,"N/A") | J11: =IFERROR((SUMPRODUCT('Reverse DCF'!$C$8*(1+J$7)^ROW(INDIRECT("1:"&'Reverse DCF'!$C$15)),(1/(1+$B11))^ROW(INDIRECT("1:"&'Reverse DCF'!$C$15)))+'Reverse DCF'!$C$8*(1+J$7)^'Reverse DCF'!$C$15*(1+'Reverse DCF'!$C$14)/($B11-'Reverse DCF'!$C$14)/(1+$B11)^'Reverse DCF'!$C$15-'Reverse DCF'!$C$10)/'Reverse DCF'!$C$9,"N/A") | ... L11: =IFERROR((SUMPRODUCT('Reverse DCF'!$C$8*(1+L$7)^ROW(INDIRECT("1:"&'Reverse DCF'!$C$15)),(1/(1+$B11))^ROW(INDIRECT("1:"&'Reverse DCF'!$C$15)))+'Reverse DCF'!$C$8*(1+L$7)^'Reverse DCF'!$C$15*(1+'Reverse DCF'!$C$14)/($B11-'Reverse DCF'!$C$14)/(1+$B11)^'Reverse DCF'!$C$15-'Reverse DCF'!$C$10)/'Reverse DCF'!$C$9,"N/A")
B12: 12% | C12: =IFERROR((SUMPRODUCT('Reverse DCF'!$C$8*(1+C$7)^ROW(INDIRECT("1:"&'Reverse DCF'!$C$15)),(1/(1+$B12))^ROW(INDIRECT("1:"&'Reverse DCF'!$C$15)))+'Reverse DCF'!$C$8*(1+C$7)^'Reverse DCF'!$C$15*(1+'Reverse DCF'!$C$14)/($B12-'Reverse DCF'!$C$14)/(1+$B12)^'Reverse DCF'!$C$15-'Reverse DCF'!$C$10)/'Reverse DCF'!$C$9,"N/A") | D12: =IFERROR((SUMPRODUCT('Reverse DCF'!$C$8*(1+D$7)^ROW(INDIRECT("1:"&'Reverse DCF'!$C$15)),(1/(1+$B12))^ROW(INDIRECT("1:"&'Reverse DCF'!$C$15)))+'Reverse DCF'!$C$8*(1+D$7)^'Reverse DCF'!$C$15*(1+'Reverse DCF'!$C$14)/($B12-'Reverse DCF'!$C$14)/(1+$B12)^'Reverse DCF'!$C$15-'Reverse DCF'!$C$10)/'Reverse DCF'!$C$9,"N/A") | E12: =IFERROR((SUMPRODUCT('Reverse DCF'!$C$8*(1+E$7)^ROW(INDIRECT("1:"&'Reverse DCF'!$C$15)),(1/(1+$B12))^ROW(INDIRECT("1:"&'Reverse DCF'!$C$15)))+'Reverse DCF'!$C$8*(1+E$7)^'Reverse DCF'!$C$15*(1+'Reverse DCF'!$C$14)/($B12-'Reverse DCF'!$C$14)/(1+$B12)^'Reverse DCF'!$C$15-'Reverse DCF'!$C$10)/'Reverse DCF'!$C$9,"N/A") | F12: =IFERROR((SUMPRODUCT('Reverse DCF'!$C$8*(1+F$7)^ROW(INDIRECT("1:"&'Reverse DCF'!$C$15)),(1/(1+$B12))^ROW(INDIRECT("1:"&'Reverse DCF'!$C$15)))+'Reverse DCF'!$C$8*(1+F$7)^'Reverse DCF'!$C$15*(1+'Reverse DCF'!$C$14)/($B12-'Reverse DCF'!$C$14)/(1+$B12)^'Reverse DCF'!$C$15-'Reverse DCF'!$C$10)/'Reverse DCF'!$C$9,"N/A") | G12: =IFERROR((SUMPRODUCT('Reverse DCF'!$C$8*(1+G$7)^ROW(INDIRECT("1:"&'Reverse DCF'!$C$15)),(1/(1+$B12))^ROW(INDIRECT("1:"&'Reverse DCF'!$C$15)))+'Reverse DCF'!$C$8*(1+G$7)^'Reverse DCF'!$C$15*(1+'Reverse DCF'!$C$14)/($B12-'Reverse DCF'!$C$14)/(1+$B12)^'Reverse DCF'!$C$15-'Reverse DCF'!$C$10)/'Reverse DCF'!$C$9,"N/A") | H12: =IFERROR((SUMPRODUCT('Reverse DCF'!$C$8*(1+H$7)^ROW(INDIRECT("1:"&'Reverse DCF'!$C$15)),(1/(1+$B12))^ROW(INDIRECT("1:"&'Reverse DCF'!$C$15)))+'Reverse DCF'!$C$8*(1+H$7)^'Reverse DCF'!$C$15*(1+'Reverse DCF'!$C$14)/($B12-'Reverse DCF'!$C$14)/(1+$B12)^'Reverse DCF'!$C$15-'Reverse DCF'!$C$10)/'Reverse DCF'!$C$9,"N/A") | I12: =IFERROR((SUMPRODUCT('Reverse DCF'!$C$8*(1+I$7)^ROW(INDIRECT("1:"&'Reverse DCF'!$C$15)),(1/(1+$B12))^ROW(INDIRECT("1:"&'Reverse DCF'!$C$15)))+'Reverse DCF'!$C$8*(1+I$7)^'Reverse DCF'!$C$15*(1+'Reverse DCF'!$C$14)/($B12-'Reverse DCF'!$C$14)/(1+$B12)^'Reverse DCF'!$C$15-'Reverse DCF'!$C$10)/'Reverse DCF'!$C$9,"N/A") | J12: =IFERROR((SUMPRODUCT('Reverse DCF'!$C$8*(1+J$7)^ROW(INDIRECT("1:"&'Reverse DCF'!$C$15)),(1/(1+$B12))^ROW(INDIRECT("1:"&'Reverse DCF'!$C$15)))+'Reverse DCF'!$C$8*(1+J$7)^'Reverse DCF'!$C$15*(1+'Reverse DCF'!$C$14)/($B12-'Reverse DCF'!$C$14)/(1+$B12)^'Reverse DCF'!$C$15-'Reverse DCF'!$C$10)/'Reverse DCF'!$C$9,"N/A") | ... L12: =IFERROR((SUMPRODUCT('Reverse DCF'!$C$8*(1+L$7)^ROW(INDIRECT("1:"&'Reverse DCF'!$C$15)),(1/(1+$B12))^ROW(INDIRECT("1:"&'Reverse DCF'!$C$15)))+'Reverse DCF'!$C$8*(1+L$7)^'Reverse DCF'!$C$15*(1+'Reverse DCF'!$C$14)/($B12-'Reverse DCF'!$C$14)/(1+$B12)^'Reverse DCF'!$C$15-'Reverse DCF'!$C$10)/'Reverse DCF'!$C$9,"N/A")
B13: 13% | C13: =IFERROR((SUMPRODUCT('Reverse DCF'!$C$8*(1+C$7)^ROW(INDIRECT("1:"&'Reverse DCF'!$C$15)),(1/(1+$B13))^ROW(INDIRECT("1:"&'Reverse DCF'!$C$15)))+'Reverse DCF'!$C$8*(1+C$7)^'Reverse DCF'!$C$15*(1+'Reverse DCF'!$C$14)/($B13-'Reverse DCF'!$C$14)/(1+$B13)^'Reverse DCF'!$C$15-'Reverse DCF'!$C$10)/'Reverse DCF'!$C$9,"N/A") | D13: =IFERROR((SUMPRODUCT('Reverse DCF'!$C$8*(1+D$7)^ROW(INDIRECT("1:"&'Reverse DCF'!$C$15)),(1/(1+$B13))^ROW(INDIRECT("1:"&'Reverse DCF'!$C$15)))+'Reverse DCF'!$C$8*(1+D$7)^'Reverse DCF'!$C$15*(1+'Reverse DCF'!$C$14)/($B13-'Reverse DCF'!$C$14)/(1+$B13)^'Reverse DCF'!$C$15-'Reverse DCF'!$C$10)/'Reverse DCF'!$C$9,"N/A") | E13: =IFERROR((SUMPRODUCT('Reverse DCF'!$C$8*(1+E$7)^ROW(INDIRECT("1:"&'Reverse DCF'!$C$15)),(1/(1+$B13))^ROW(INDIRECT("1:"&'Reverse DCF'!$C$15)))+'Reverse DCF'!$C$8*(1+E$7)^'Reverse DCF'!$C$15*(1+'Reverse DCF'!$C$14)/($B13-'Reverse DCF'!$C$14)/(1+$B13)^'Reverse DCF'!$C$15-'Reverse DCF'!$C$10)/'Reverse DCF'!$C$9,"N/A") | F13: =IFERROR((SUMPRODUCT('Reverse DCF'!$C$8*(1+F$7)^ROW(INDIRECT("1:"&'Reverse DCF'!$C$15)),(1/(1+$B13))^ROW(INDIRECT("1:"&'Reverse DCF'!$C$15)))+'Reverse DCF'!$C$8*(1+F$7)^'Reverse DCF'!$C$15*(1+'Reverse DCF'!$C$14)/($B13-'Reverse DCF'!$C$14)/(1+$B13)^'Reverse DCF'!$C$15-'Reverse DCF'!$C$10)/'Reverse DCF'!$C$9,"N/A") | G13: =IFERROR((SUMPRODUCT('Reverse DCF'!$C$8*(1+G$7)^ROW(INDIRECT("1:"&'Reverse DCF'!$C$15)),(1/(1+$B13))^ROW(INDIRECT("1:"&'Reverse DCF'!$C$15)))+'Reverse DCF'!$C$8*(1+G$7)^'Reverse DCF'!$C$15*(1+'Reverse DCF'!$C$14)/($B13-'Reverse DCF'!$C$14)/(1+$B13)^'Reverse DCF'!$C$15-'Reverse DCF'!$C$10)/'Reverse DCF'!$C$9,"N/A") | H13: =IFERROR((SUMPRODUCT('Reverse DCF'!$C$8*(1+H$7)^ROW(INDIRECT("1:"&'Reverse DCF'!$C$15)),(1/(1+$B13))^ROW(INDIRECT("1:"&'Reverse DCF'!$C$15)))+'Reverse DCF'!$C$8*(1+H$7)^'Reverse DCF'!$C$15*(1+'Reverse DCF'!$C$14)/($B13-'Reverse DCF'!$C$14)/(1+$B13)^'Reverse DCF'!$C$15-'Reverse DCF'!$C$10)/'Reverse DCF'!$C$9,"N/A") | I13: =IFERROR((SUMPRODUCT('Reverse DCF'!$C$8*(1+I$7)^ROW(INDIRECT("1:"&'Reverse DCF'!$C$15)),(1/(1+$B13))^ROW(INDIRECT("1:"&'Reverse DCF'!$C$15)))+'Reverse DCF'!$C$8*(1+I$7)^'Reverse DCF'!$C$15*(1+'Reverse DCF'!$C$14)/($B13-'Reverse DCF'!$C$14)/(1+$B13)^'Reverse DCF'!$C$15-'Reverse DCF'!$C$10)/'Reverse DCF'!$C$9,"N/A") | J13: =IFERROR((SUMPRODUCT('Reverse DCF'!$C$8*(1+J$7)^ROW(INDIRECT("1:"&'Reverse DCF'!$C$15)),(1/(1+$B13))^ROW(INDIRECT("1:"&'Reverse DCF'!$C$15)))+'Reverse DCF'!$C$8*(1+J$7)^'Reverse DCF'!$C$15*(1+'Reverse DCF'!$C$14)/($B13-'Reverse DCF'!$C$14)/(1+$B13)^'Reverse DCF'!$C$15-'Reverse DCF'!$C$10)/'Reverse DCF'!$C$9,"N/A") | ... L13: =IFERROR((SUMPRODUCT('Reverse DCF'!$C$8*(1+L$7)^ROW(INDIRECT("1:"&'Reverse DCF'!$C$15)),(1/(1+$B13))^ROW(INDIRECT("1:"&'Reverse DCF'!$C$15)))+'Reverse DCF'!$C$8*(1+L$7)^'Reverse DCF'!$C$15*(1+'Reverse DCF'!$C$14)/($B13-'Reverse DCF'!$C$14)/(1+$B13)^'Reverse DCF'!$C$15-'Reverse DCF'!$C$10)/'Reverse DCF'!$C$9,"N/A")
B14: 14% | C14: =IFERROR((SUMPRODUCT('Reverse DCF'!$C$8*(1+C$7)^ROW(INDIRECT("1:"&'Reverse DCF'!$C$15)),(1/(1+$B14))^ROW(INDIRECT("1:"&'Reverse DCF'!$C$15)))+'Reverse DCF'!$C$8*(1+C$7)^'Reverse DCF'!$C$15*(1+'Reverse DCF'!$C$14)/($B14-'Reverse DCF'!$C$14)/(1+$B14)^'Reverse DCF'!$C$15-'Reverse DCF'!$C$10)/'Reverse DCF'!$C$9,"N/A") | D14: =IFERROR((SUMPRODUCT('Reverse DCF'!$C$8*(1+D$7)^ROW(INDIRECT("1:"&'Reverse DCF'!$C$15)),(1/(1+$B14))^ROW(INDIRECT("1:"&'Reverse DCF'!$C$15)))+'Reverse DCF'!$C$8*(1+D$7)^'Reverse DCF'!$C$15*(1+'Reverse DCF'!$C$14)/($B14-'Reverse DCF'!$C$14)/(1+$B14)^'Reverse DCF'!$C$15-'Reverse DCF'!$C$10)/'Reverse DCF'!$C$9,"N/A") | E14: =IFERROR((SUMPRODUCT('Reverse DCF'!$C$8*(1+E$7)^ROW(INDIRECT("1:"&'Reverse DCF'!$C$15)),(1/(1+$B14))^ROW(INDIRECT("1:"&'Reverse DCF'!$C$15)))+'Reverse DCF'!$C$8*(1+E$7)^'Reverse DCF'!$C$15*(1+'Reverse DCF'!$C$14)/($B14-'Reverse DCF'!$C$14)/(1+$B14)^'Reverse DCF'!$C$15-'Reverse DCF'!$C$10)/'Reverse DCF'!$C$9,"N/A") | F14: =IFERROR((SUMPRODUCT('Reverse DCF'!$C$8*(1+F$7)^ROW(INDIRECT("1:"&'Reverse DCF'!$C$15)),(1/(1+$B14))^ROW(INDIRECT("1:"&'Reverse DCF'!$C$15)))+'Reverse DCF'!$C$8*(1+F$7)^'Reverse DCF'!$C$15*(1+'Reverse DCF'!$C$14)/($B14-'Reverse DCF'!$C$14)/(1+$B14)^'Reverse DCF'!$C$15-'Reverse DCF'!$C$10)/'Reverse DCF'!$C$9,"N/A") | G14: =IFERROR((SUMPRODUCT('Reverse DCF'!$C$8*(1+G$7)^ROW(INDIRECT("1:"&'Reverse DCF'!$C$15)),(1/(1+$B14))^ROW(INDIRECT("1:"&'Reverse DCF'!$C$15)))+'Reverse DCF'!$C$8*(1+G$7)^'Reverse DCF'!$C$15*(1+'Reverse DCF'!$C$14)/($B14-'Reverse DCF'!$C$14)/(1+$B14)^'Reverse DCF'!$C$15-'Reverse DCF'!$C$10)/'Reverse DCF'!$C$9,"N/A") | H14: =IFERROR((SUMPRODUCT('Reverse DCF'!$C$8*(1+H$7)^ROW(INDIRECT("1:"&'Reverse DCF'!$C$15)),(1/(1+$B14))^ROW(INDIRECT("1:"&'Reverse DCF'!$C$15)))+'Reverse DCF'!$C$8*(1+H$7)^'Reverse DCF'!$C$15*(1+'Reverse DCF'!$C$14)/($B14-'Reverse DCF'!$C$14)/(1+$B14)^'Reverse DCF'!$C$15-'Reverse DCF'!$C$10)/'Reverse DCF'!$C$9,"N/A") | I14: =IFERROR((SUMPRODUCT('Reverse DCF'!$C$8*(1+I$7)^ROW(INDIRECT("1:"&'Reverse DCF'!$C$15)),(1/(1+$B14))^ROW(INDIRECT("1:"&'Reverse DCF'!$C$15)))+'Reverse DCF'!$C$8*(1+I$7)^'Reverse DCF'!$C$15*(1+'Reverse DCF'!$C$14)/($B14-'Reverse DCF'!$C$14)/(1+$B14)^'Reverse DCF'!$C$15-'Reverse DCF'!$C$10)/'Reverse DCF'!$C$9,"N/A") | J14: =IFERROR((SUMPRODUCT('Reverse DCF'!$C$8*(1+J$7)^ROW(INDIRECT("1:"&'Reverse DCF'!$C$15)),(1/(1+$B14))^ROW(INDIRECT("1:"&'Reverse DCF'!$C$15)))+'Reverse DCF'!$C$8*(1+J$7)^'Reverse DCF'!$C$15*(1+'Reverse DCF'!$C$14)/($B14-'Reverse DCF'!$C$14)/(1+$B14)^'Reverse DCF'!$C$15-'Reverse DCF'!$C$10)/'Reverse DCF'!$C$9,"N/A") | ... L14: =IFERROR((SUMPRODUCT('Reverse DCF'!$C$8*(1+L$7)^ROW(INDIRECT("1:"&'Reverse DCF'!$C$15)),(1/(1+$B14))^ROW(INDIRECT("1:"&'Reverse DCF'!$C$15)))+'Reverse DCF'!$C$8*(1+L$7)^'Reverse DCF'!$C$15*(1+'Reverse DCF'!$C$14)/($B14-'Reverse DCF'!$C$14)/(1+$B14)^'Reverse DCF'!$C$15-'Reverse DCF'!$C$10)/'Reverse DCF'!$C$9,"N/A")
B15: 15% | C15: =IFERROR((SUMPRODUCT('Reverse DCF'!$C$8*(1+C$7)^ROW(INDIRECT("1:"&'Reverse DCF'!$C$15)),(1/(1+$B15))^ROW(INDIRECT("1:"&'Reverse DCF'!$C$15)))+'Reverse DCF'!$C$8*(1+C$7)^'Reverse DCF'!$C$15*(1+'Reverse DCF'!$C$14)/($B15-'Reverse DCF'!$C$14)/(1+$B15)^'Reverse DCF'!$C$15-'Reverse DCF'!$C$10)/'Reverse DCF'!$C$9,"N/A") | D15: =IFERROR((SUMPRODUCT('Reverse DCF'!$C$8*(1+D$7)^ROW(INDIRECT("1:"&'Reverse DCF'!$C$15)),(1/(1+$B15))^ROW(INDIRECT("1:"&'Reverse DCF'!$C$15)))+'Reverse DCF'!$C$8*(1+D$7)^'Reverse DCF'!$C$15*(1+'Reverse DCF'!$C$14)/($B15-'Reverse DCF'!$C$14)/(1+$B15)^'Reverse DCF'!$C$15-'Reverse DCF'!$C$10)/'Reverse DCF'!$C$9,"N/A") | E15: =IFERROR((SUMPRODUCT('Reverse DCF'!$C$8*(1+E$7)^ROW(INDIRECT("1:"&'Reverse DCF'!$C$15)),(1/(1+$B15))^ROW(INDIRECT("1:"&'Reverse DCF'!$C$15)))+'Reverse DCF'!$C$8*(1+E$7)^'Reverse DCF'!$C$15*(1+'Reverse DCF'!$C$14)/($B15-'Reverse DCF'!$C$14)/(1+$B15)^'Reverse DCF'!$C$15-'Reverse DCF'!$C$10)/'Reverse DCF'!$C$9,"N/A") | F15: =IFERROR((SUMPRODUCT('Reverse DCF'!$C$8*(1+F$7)^ROW(INDIRECT("1:"&'Reverse DCF'!$C$15)),(1/(1+$B15))^ROW(INDIRECT("1:"&'Reverse DCF'!$C$15)))+'Reverse DCF'!$C$8*(1+F$7)^'Reverse DCF'!$C$15*(1+'Reverse DCF'!$C$14)/($B15-'Reverse DCF'!$C$14)/(1+$B15)^'Reverse DCF'!$C$15-'Reverse DCF'!$C$10)/'Reverse DCF'!$C$9,"N/A") | G15: =IFERROR((SUMPRODUCT('Reverse DCF'!$C$8*(1+G$7)^ROW(INDIRECT("1:"&'Reverse DCF'!$C$15)),(1/(1+$B15))^ROW(INDIRECT("1:"&'Reverse DCF'!$C$15)))+'Reverse DCF'!$C$8*(1+G$7)^'Reverse DCF'!$C$15*(1+'Reverse DCF'!$C$14)/($B15-'Reverse DCF'!$C$14)/(1+$B15)^'Reverse DCF'!$C$15-'Reverse DCF'!$C$10)/'Reverse DCF'!$C$9,"N/A") | H15: =IFERROR((SUMPRODUCT('Reverse DCF'!$C$8*(1+H$7)^ROW(INDIRECT("1:"&'Reverse DCF'!$C$15)),(1/(1+$B15))^ROW(INDIRECT("1:"&'Reverse DCF'!$C$15)))+'Reverse DCF'!$C$8*(1+H$7)^'Reverse DCF'!$C$15*(1+'Reverse DCF'!$C$14)/($B15-'Reverse DCF'!$C$14)/(1+$B15)^'Reverse DCF'!$C$15-'Reverse DCF'!$C$10)/'Reverse DCF'!$C$9,"N/A") | I15: =IFERROR((SUMPRODUCT('Reverse DCF'!$C$8*(1+I$7)^ROW(INDIRECT("1:"&'Reverse DCF'!$C$15)),(1/(1+$B15))^ROW(INDIRECT("1:"&'Reverse DCF'!$C$15)))+'Reverse DCF'!$C$8*(1+I$7)^'Reverse DCF'!$C$15*(1+'Reverse DCF'!$C$14)/($B15-'Reverse DCF'!$C$14)/(1+$B15)^'Reverse DCF'!$C$15-'Reverse DCF'!$C$10)/'Reverse DCF'!$C$9,"N/A") | J15: =IFERROR((SUMPRODUCT('Reverse DCF'!$C$8*(1+J$7)^ROW(INDIRECT("1:"&'Reverse DCF'!$C$15)),(1/(1+$B15))^ROW(INDIRECT("1:"&'Reverse DCF'!$C$15)))+'Reverse DCF'!$C$8*(1+J$7)^'Reverse DCF'!$C$15*(1+'Reverse DCF'!$C$14)/($B15-'Reverse DCF'!$C$14)/(1+$B15)^'Reverse DCF'!$C$15-'Reverse DCF'!$C$10)/'Reverse DCF'!$C$9,"N/A") | ... L15: =IFERROR((SUMPRODUCT('Reverse DCF'!$C$8*(1+L$7)^ROW(INDIRECT("1:"&'Reverse DCF'!$C$15)),(1/(1+$B15))^ROW(INDIRECT("1:"&'Reverse DCF'!$C$15)))+'Reverse DCF'!$C$8*(1+L$7)^'Reverse DCF'!$C$15*(1+'Reverse DCF'!$C$14)/($B15-'Reverse DCF'!$C$14)/(1+$B15)^'Reverse DCF'!$C$15-'Reverse DCF'!$C$10)/'Reverse DCF'!$C$9,"N/A")
B16: 16% | C16: =IFERROR((SUMPRODUCT('Reverse DCF'!$C$8*(1+C$7)^ROW(INDIRECT("1:"&'Reverse DCF'!$C$15)),(1/(1+$B16))^ROW(INDIRECT("1:"&'Reverse DCF'!$C$15)))+'Reverse DCF'!$C$8*(1+C$7)^'Reverse DCF'!$C$15*(1+'Reverse DCF'!$C$14)/($B16-'Reverse DCF'!$C$14)/(1+$B16)^'Reverse DCF'!$C$15-'Reverse DCF'!$C$10)/'Reverse DCF'!$C$9,"N/A") | D16: =IFERROR((SUMPRODUCT('Reverse DCF'!$C$8*(1+D$7)^ROW(INDIRECT("1:"&'Reverse DCF'!$C$15)),(1/(1+$B16))^ROW(INDIRECT("1:"&'Reverse DCF'!$C$15)))+'Reverse DCF'!$C$8*(1+D$7)^'Reverse DCF'!$C$15*(1+'Reverse DCF'!$C$14)/($B16-'Reverse DCF'!$C$14)/(1+$B16)^'Reverse DCF'!$C$15-'Reverse DCF'!$C$10)/'Reverse DCF'!$C$9,"N/A") | E16: =IFERROR((SUMPRODUCT('Reverse DCF'!$C$8*(1+E$7)^ROW(INDIRECT("1:"&'Reverse DCF'!$C$15)),(1/(1+$B16))^ROW(INDIRECT("1:"&'Reverse DCF'!$C$15)))+'Reverse DCF'!$C$8*(1+E$7)^'Reverse DCF'!$C$15*(1+'Reverse DCF'!$C$14)/($B16-'Reverse DCF'!$C$14)/(1+$B16)^'Reverse DCF'!$C$15-'Reverse DCF'!$C$10)/'Reverse DCF'!$C$9,"N/A") | F16: =IFERROR((SUMPRODUCT('Reverse DCF'!$C$8*(1+F$7)^ROW(INDIRECT("1:"&'Reverse DCF'!$C$15)),(1/(1+$B16))^ROW(INDIRECT("1:"&'Reverse DCF'!$C$15)))+'Reverse DCF'!$C$8*(1+F$7)^'Reverse DCF'!$C$15*(1+'Reverse DCF'!$C$14)/($B16-'Reverse DCF'!$C$14)/(1+$B16)^'Reverse DCF'!$C$15-'Reverse DCF'!$C$10)/'Reverse DCF'!$C$9,"N/A") | G16: =IFERROR((SUMPRODUCT('Reverse DCF'!$C$8*(1+G$7)^ROW(INDIRECT("1:"&'Reverse DCF'!$C$15)),(1/(1+$B16))^ROW(INDIRECT("1:"&'Reverse DCF'!$C$15)))+'Reverse DCF'!$C$8*(1+G$7)^'Reverse DCF'!$C$15*(1+'Reverse DCF'!$C$14)/($B16-'Reverse DCF'!$C$14)/(1+$B16)^'Reverse DCF'!$C$15-'Reverse DCF'!$C$10)/'Reverse DCF'!$C$9,"N/A") | H16: =IFERROR((SUMPRODUCT('Reverse DCF'!$C$8*(1+H$7)^ROW(INDIRECT("1:"&'Reverse DCF'!$C$15)),(1/(1+$B16))^ROW(INDIRECT("1:"&'Reverse DCF'!$C$15)))+'Reverse DCF'!$C$8*(1+H$7)^'Reverse DCF'!$C$15*(1+'Reverse DCF'!$C$14)/($B16-'Reverse DCF'!$C$14)/(1+$B16)^'Reverse DCF'!$C$15-'Reverse DCF'!$C$10)/'Reverse DCF'!$C$9,"N/A") | I16: =IFERROR((SUMPRODUCT('Reverse DCF'!$C$8*(1+I$7)^ROW(INDIRECT("1:"&'Reverse DCF'!$C$15)),(1/(1+$B16))^ROW(INDIRECT("1:"&'Reverse DCF'!$C$15)))+'Reverse DCF'!$C$8*(1+I$7)^'Reverse DCF'!$C$15*(1+'Reverse DCF'!$C$14)/($B16-'Reverse DCF'!$C$14)/(1+$B16)^'Reverse DCF'!$C$15-'Reverse DCF'!$C$10)/'Reverse DCF'!$C$9,"N/A") | J16: =IFERROR((SUMPRODUCT('Reverse DCF'!$C$8*(1+J$7)^ROW(INDIRECT("1:"&'Reverse DCF'!$C$15)),(1/(1+$B16))^ROW(INDIRECT("1:"&'Reverse DCF'!$C$15)))+'Reverse DCF'!$C$8*(1+J$7)^'Reverse DCF'!$C$15*(1+'Reverse DCF'!$C$14)/($B16-'Reverse DCF'!$C$14)/(1+$B16)^'Reverse DCF'!$C$15-'Reverse DCF'!$C$10)/'Reverse DCF'!$C$9,"N/A") | ... L16: =IFERROR((SUMPRODUCT('Reverse DCF'!$C$8*(1+L$7)^ROW(INDIRECT("1:"&'Reverse DCF'!$C$15)),(1/(1+$B16))^ROW(INDIRECT("1:"&'Reverse DCF'!$C$15)))+'Reverse DCF'!$C$8*(1+L$7)^'Reverse DCF'!$C$15*(1+'Reverse DCF'!$C$14)/($B16-'Reverse DCF'!$C$14)/(1+$B16)^'Reverse DCF'!$C$15-'Reverse DCF'!$C$10)/'Reverse DCF'!$C$9,"N/A")
B20: SENSITIVITY: WACC vs TERMINAL GROWTH RATE → Implied FCF Growth Rate | J20: Note: values shown are approximate implied growth rates at the given WACC and terminal growth rate combinations, using the current stock price from the Reverse DCF sheet.
B21: WACC ↓ / Term.G → | C21: 2.0% | D21: 2.5% | E21: 3.0% | F21: 3.5% | G21: 4.0% | H21: 4.5% | I21: 5.0%
B22: 8% | C22: =IFERROR((SUMPRODUCT('Reverse DCF'!$C$8*(1+'Reverse DCF'!$C$19)^ROW(INDIRECT("1:"&'Reverse DCF'!$C$15)),(1/(1+$B22))^ROW(INDIRECT("1:"&'Reverse DCF'!$C$15)))+'Reverse DCF'!$C$8*(1+'Reverse DCF'!$C$19)^'Reverse DCF'!$C$15*(1+C$21)/($B22-C$21)/(1+$B22)^'Reverse DCF'!$C$15-'Reverse DCF'!$C$10)/'Reverse DCF'!$C$9,"N/A") | D22: =IFERROR((SUMPRODUCT('Reverse DCF'!$C$8*(1+'Reverse DCF'!$C$19)^ROW(INDIRECT("1:"&'Reverse DCF'!$C$15)),(1/(1+$B22))^ROW(INDIRECT("1:"&'Reverse DCF'!$C$15)))+'Reverse DCF'!$C$8*(1+'Reverse DCF'!$C$19)^'Reverse DCF'!$C$15*(1+D$21)/($B22-D$21)/(1+$B22)^'Reverse DCF'!$C$15-'Reverse DCF'!$C$10)/'Reverse DCF'!$C$9,"N/A") | E22: =IFERROR((SUMPRODUCT('Reverse DCF'!$C$8*(1+'Reverse DCF'!$C$19)^ROW(INDIRECT("1:"&'Reverse DCF'!$C$15)),(1/(1+$B22))^ROW(INDIRECT("1:"&'Reverse DCF'!$C$15)))+'Reverse DCF'!$C$8*(1+'Reverse DCF'!$C$19)^'Reverse DCF'!$C$15*(1+E$21)/($B22-E$21)/(1+$B22)^'Reverse DCF'!$C$15-'Reverse DCF'!$C$10)/'Reverse DCF'!$C$9,"N/A") | F22: =IFERROR((SUMPRODUCT('Reverse DCF'!$C$8*(1+'Reverse DCF'!$C$19)^ROW(INDIRECT("1:"&'Reverse DCF'!$C$15)),(1/(1+$B22))^ROW(INDIRECT("1:"&'Reverse DCF'!$C$15)))+'Reverse DCF'!$C$8*(1+'Reverse DCF'!$C$19)^'Reverse DCF'!$C$15*(1+F$21)/($B22-F$21)/(1+$B22)^'Reverse DCF'!$C$15-'Reverse DCF'!$C$10)/'Reverse DCF'!$C$9,"N/A") | G22: =IFERROR((SUMPRODUCT('Reverse DCF'!$C$8*(1+'Reverse DCF'!$C$19)^ROW(INDIRECT("1:"&'Reverse DCF'!$C$15)),(1/(1+$B22))^ROW(INDIRECT("1:"&'Reverse DCF'!$C$15)))+'Reverse DCF'!$C$8*(1+'Reverse DCF'!$C$19)^'Reverse DCF'!$C$15*(1+G$21)/($B22-G$21)/(1+$B22)^'Reverse DCF'!$C$15-'Reverse DCF'!$C$10)/'Reverse DCF'!$C$9,"N/A") | H22: =IFERROR((SUMPRODUCT('Reverse DCF'!$C$8*(1+'Reverse DCF'!$C$19)^ROW(INDIRECT("1:"&'Reverse DCF'!$C$15)),(1/(1+$B22))^ROW(INDIRECT("1:"&'Reverse DCF'!$C$15)))+'Reverse DCF'!$C$8*(1+'Reverse DCF'!$C$19)^'Reverse DCF'!$C$15*(1+H$21)/($B22-H$21)/(1+$B22)^'Reverse DCF'!$C$15-'Reverse DCF'!$C$10)/'Reverse DCF'!$C$9,"N/A") | I22: =IFERROR((SUMPRODUCT('Reverse DCF'!$C$8*(1+'Reverse DCF'!$C$19)^ROW(INDIRECT("1:"&'Reverse DCF'!$C$15)),(1/(1+$B22))^ROW(INDIRECT("1:"&'Reverse DCF'!$C$15)))+'Reverse DCF'!$C$8*(1+'Reverse DCF'!$C$19)^'Reverse DCF'!$C$15*(1+I$21)/($B22-I$21)/(1+$B22)^'Reverse DCF'!$C$15-'Reverse DCF'!$C$10)/'Reverse DCF'!$C$9,"N/A")
B23: 9% | C23: =IFERROR((SUMPRODUCT('Reverse DCF'!$C$8*(1+'Reverse DCF'!$C$19)^ROW(INDIRECT("1:"&'Reverse DCF'!$C$15)),(1/(1+$B23))^ROW(INDIRECT("1:"&'Reverse DCF'!$C$15)))+'Reverse DCF'!$C$8*(1+'Reverse DCF'!$C$19)^'Reverse DCF'!$C$15*(1+C$21)/($B23-C$21)/(1+$B23)^'Reverse DCF'!$C$15-'Reverse DCF'!$C$10)/'Reverse DCF'!$C$9,"N/A") | D23: =IFERROR((SUMPRODUCT('Reverse DCF'!$C$8*(1+'Reverse DCF'!$C$19)^ROW(INDIRECT("1:"&'Reverse DCF'!$C$15)),(1/(1+$B23))^ROW(INDIRECT("1:"&'Reverse DCF'!$C$15)))+'Reverse DCF'!$C$8*(1+'Reverse DCF'!$C$19)^'Reverse DCF'!$C$15*(1+D$21)/($B23-D$21)/(1+$B23)^'Reverse DCF'!$C$15-'Reverse DCF'!$C$10)/'Reverse DCF'!$C$9,"N/A") | E23: =IFERROR((SUMPRODUCT('Reverse DCF'!$C$8*(1+'Reverse DCF'!$C$19)^ROW(INDIRECT("1:"&'Reverse DCF'!$C$15)),(1/(1+$B23))^ROW(INDIRECT("1:"&'Reverse DCF'!$C$15)))+'Reverse DCF'!$C$8*(1+'Reverse DCF'!$C$19)^'Reverse DCF'!$C$15*(1+E$21)/($B23-E$21)/(1+$B23)^'Reverse DCF'!$C$15-'Reverse DCF'!$C$10)/'Reverse DCF'!$C$9,"N/A") | F23: =IFERROR((SUMPRODUCT('Reverse DCF'!$C$8*(1+'Reverse DCF'!$C$19)^ROW(INDIRECT("1:"&'Reverse DCF'!$C$15)),(1/(1+$B23))^ROW(INDIRECT("1:"&'Reverse DCF'!$C$15)))+'Reverse DCF'!$C$8*(1+'Reverse DCF'!$C$19)^'Reverse DCF'!$C$15*(1+F$21)/($B23-F$21)/(1+$B23)^'Reverse DCF'!$C$15-'Reverse DCF'!$C$10)/'Reverse DCF'!$C$9,"N/A") | G23: =IFERROR((SUMPRODUCT('Reverse DCF'!$C$8*(1+'Reverse DCF'!$C$19)^ROW(INDIRECT("1:"&'Reverse DCF'!$C$15)),(1/(1+$B23))^ROW(INDIRECT("1:"&'Reverse DCF'!$C$15)))+'Reverse DCF'!$C$8*(1+'Reverse DCF'!$C$19)^'Reverse DCF'!$C$15*(1+G$21)/($B23-G$21)/(1+$B23)^'Reverse DCF'!$C$15-'Reverse DCF'!$C$10)/'Reverse DCF'!$C$9,"N/A") | H23: =IFERROR((SUMPRODUCT('Reverse DCF'!$C$8*(1+'Reverse DCF'!$C$19)^ROW(INDIRECT("1:"&'Reverse DCF'!$C$15)),(1/(1+$B23))^ROW(INDIRECT("1:"&'Reverse DCF'!$C$15)))+'Reverse DCF'!$C$8*(1+'Reverse DCF'!$C$19)^'Reverse DCF'!$C$15*(1+H$21)/($B23-H$21)/(1+$B23)^'Reverse DCF'!$C$15-'Reverse DCF'!$C$10)/'Reverse DCF'!$C$9,"N/A") | I23: =IFERROR((SUMPRODUCT('Reverse DCF'!$C$8*(1+'Reverse DCF'!$C$19)^ROW(INDIRECT("1:"&'Reverse DCF'!$C$15)),(1/(1+$B23))^ROW(INDIRECT("1:"&'Reverse DCF'!$C$15)))+'Reverse DCF'!$C$8*(1+'Reverse DCF'!$C$19)^'Reverse DCF'!$C$15*(1+I$21)/($B23-I$21)/(1+$B23)^'Reverse DCF'!$C$15-'Reverse DCF'!$C$10)/'Reverse DCF'!$C$9,"N/A")
B24: 10% | C24: =IFERROR((SUMPRODUCT('Reverse DCF'!$C$8*(1+'Reverse DCF'!$C$19)^ROW(INDIRECT("1:"&'Reverse DCF'!$C$15)),(1/(1+$B24))^ROW(INDIRECT("1:"&'Reverse DCF'!$C$15)))+'Reverse DCF'!$C$8*(1+'Reverse DCF'!$C$19)^'Reverse DCF'!$C$15*(1+C$21)/($B24-C$21)/(1+$B24)^'Reverse DCF'!$C$15-'Reverse DCF'!$C$10)/'Reverse DCF'!$C$9,"N/A") | D24: =IFERROR((SUMPRODUCT('Reverse DCF'!$C$8*(1+'Reverse DCF'!$C$19)^ROW(INDIRECT("1:"&'Reverse DCF'!$C$15)),(1/(1+$B24))^ROW(INDIRECT("1:"&'Reverse DCF'!$C$15)))+'Reverse DCF'!$C$8*(1+'Reverse DCF'!$C$19)^'Reverse DCF'!$C$15*(1+D$21)/($B24-D$21)/(1+$B24)^'Reverse DCF'!$C$15-'Reverse DCF'!$C$10)/'Reverse DCF'!$C$9,"N/A") | E24: =IFERROR((SUMPRODUCT('Reverse DCF'!$C$8*(1+'Reverse DCF'!$C$19)^ROW(INDIRECT("1:"&'Reverse DCF'!$C$15)),(1/(1+$B24))^ROW(INDIRECT("1:"&'Reverse DCF'!$C$15)))+'Reverse DCF'!$C$8*(1+'Reverse DCF'!$C$19)^'Reverse DCF'!$C$15*(1+E$21)/($B24-E$21)/(1+$B24)^'Reverse DCF'!$C$15-'Reverse DCF'!$C$10)/'Reverse DCF'!$C$9,"N/A") | F24: =IFERROR((SUMPRODUCT('Reverse DCF'!$C$8*(1+'Reverse DCF'!$C$19)^ROW(INDIRECT("1:"&'Reverse DCF'!$C$15)),(1/(1+$B24))^ROW(INDIRECT("1:"&'Reverse DCF'!$C$15)))+'Reverse DCF'!$C$8*(1+'Reverse DCF'!$C$19)^'Reverse DCF'!$C$15*(1+F$21)/($B24-F$21)/(1+$B24)^'Reverse DCF'!$C$15-'Reverse DCF'!$C$10)/'Reverse DCF'!$C$9,"N/A") | G24: =IFERROR((SUMPRODUCT('Reverse DCF'!$C$8*(1+'Reverse DCF'!$C$19)^ROW(INDIRECT("1:"&'Reverse DCF'!$C$15)),(1/(1+$B24))^ROW(INDIRECT("1:"&'Reverse DCF'!$C$15)))+'Reverse DCF'!$C$8*(1+'Reverse DCF'!$C$19)^'Reverse DCF'!$C$15*(1+G$21)/($B24-G$21)/(1+$B24)^'Reverse DCF'!$C$15-'Reverse DCF'!$C$10)/'Reverse DCF'!$C$9,"N/A") | H24: =IFERROR((SUMPRODUCT('Reverse DCF'!$C$8*(1+'Reverse DCF'!$C$19)^ROW(INDIRECT("1:"&'Reverse DCF'!$C$15)),(1/(1+$B24))^ROW(INDIRECT("1:"&'Reverse DCF'!$C$15)))+'Reverse DCF'!$C$8*(1+'Reverse DCF'!$C$19)^'Reverse DCF'!$C$15*(1+H$21)/($B24-H$21)/(1+$B24)^'Reverse DCF'!$C$15-'Reverse DCF'!$C$10)/'Reverse DCF'!$C$9,"N/A") | I24: =IFERROR((SUMPRODUCT('Reverse DCF'!$C$8*(1+'Reverse DCF'!$C$19)^ROW(INDIRECT("1:"&'Reverse DCF'!$C$15)),(1/(1+$B24))^ROW(INDIRECT("1:"&'Reverse DCF'!$C$15)))+'Reverse DCF'!$C$8*(1+'Reverse DCF'!$C$19)^'Reverse DCF'!$C$15*(1+I$21)/($B24-I$21)/(1+$B24)^'Reverse DCF'!$C$15-'Reverse DCF'!$C$10)/'Reverse DCF'!$C$9,"N/A")
B25: 11% | C25: =IFERROR((SUMPRODUCT('Reverse DCF'!$C$8*(1+'Reverse DCF'!$C$19)^ROW(INDIRECT("1:"&'Reverse DCF'!$C$15)),(1/(1+$B25))^ROW(INDIRECT("1:"&'Reverse DCF'!$C$15)))+'Reverse DCF'!$C$8*(1+'Reverse DCF'!$C$19)^'Reverse DCF'!$C$15*(1+C$21)/($B25-C$21)/(1+$B25)^'Reverse DCF'!$C$15-'Reverse DCF'!$C$10)/'Reverse DCF'!$C$9,"N/A") | D25: =IFERROR((SUMPRODUCT('Reverse DCF'!$C$8*(1+'Reverse DCF'!$C$19)^ROW(INDIRECT("1:"&'Reverse DCF'!$C$15)),(1/(1+$B25))^ROW(INDIRECT("1:"&'Reverse DCF'!$C$15)))+'Reverse DCF'!$C$8*(1+'Reverse DCF'!$C$19)^'Reverse DCF'!$C$15*(1+D$21)/($B25-D$21)/(1+$B25)^'Reverse DCF'!$C$15-'Reverse DCF'!$C$10)/'Reverse DCF'!$C$9,"N/A") | E25: =IFERROR((SUMPRODUCT('Reverse DCF'!$C$8*(1+'Reverse DCF'!$C$19)^ROW(INDIRECT("1:"&'Reverse DCF'!$C$15)),(1/(1+$B25))^ROW(INDIRECT("1:"&'Reverse DCF'!$C$15)))+'Reverse DCF'!$C$8*(1+'Reverse DCF'!$C$19)^'Reverse DCF'!$C$15*(1+E$21)/($B25-E$21)/(1+$B25)^'Reverse DCF'!$C$15-'Reverse DCF'!$C$10)/'Reverse DCF'!$C$9,"N/A") | F25: =IFERROR((SUMPRODUCT('Reverse DCF'!$C$8*(1+'Reverse DCF'!$C$19)^ROW(INDIRECT("1:"&'Reverse DCF'!$C$15)),(1/(1+$B25))^ROW(INDIRECT("1:"&'Reverse DCF'!$C$15)))+'Reverse DCF'!$C$8*(1+'Reverse DCF'!$C$19)^'Reverse DCF'!$C$15*(1+F$21)/($B25-F$21)/(1+$B25)^'Reverse DCF'!$C$15-'Reverse DCF'!$C$10)/'Reverse DCF'!$C$9,"N/A") | G25: =IFERROR((SUMPRODUCT('Reverse DCF'!$C$8*(1+'Reverse DCF'!$C$19)^ROW(INDIRECT("1:"&'Reverse DCF'!$C$15)),(1/(1+$B25))^ROW(INDIRECT("1:"&'Reverse DCF'!$C$15)))+'Reverse DCF'!$C$8*(1+'Reverse DCF'!$C$19)^'Reverse DCF'!$C$15*(1+G$21)/($B25-G$21)/(1+$B25)^'Reverse DCF'!$C$15-'Reverse DCF'!$C$10)/'Reverse DCF'!$C$9,"N/A") | H25: =IFERROR((SUMPRODUCT('Reverse DCF'!$C$8*(1+'Reverse DCF'!$C$19)^ROW(INDIRECT("1:"&'Reverse DCF'!$C$15)),(1/(1+$B25))^ROW(INDIRECT("1:"&'Reverse DCF'!$C$15)))+'Reverse DCF'!$C$8*(1+'Reverse DCF'!$C$19)^'Reverse DCF'!$C$15*(1+H$21)/($B25-H$21)/(1+$B25)^'Reverse DCF'!$C$15-'Reverse DCF'!$C$10)/'Reverse DCF'!$C$9,"N/A") | I25: =IFERROR((SUMPRODUCT('Reverse DCF'!$C$8*(1+'Reverse DCF'!$C$19)^ROW(INDIRECT("1:"&'Reverse DCF'!$C$15)),(1/(1+$B25))^ROW(INDIRECT("1:"&'Reverse DCF'!$C$15)))+'Reverse DCF'!$C$8*(1+'Reverse DCF'!$C$19)^'Reverse DCF'!$C$15*(1+I$21)/($B25-I$21)/(1+$B25)^'Reverse DCF'!$C$15-'Reverse DCF'!$C$10)/'Reverse DCF'!$C$9,"N/A")
B26: 12% | C26: =IFERROR((SUMPRODUCT('Reverse DCF'!$C$8*(1+'Reverse DCF'!$C$19)^ROW(INDIRECT("1:"&'Reverse DCF'!$C$15)),(1/(1+$B26))^ROW(INDIRECT("1:"&'Reverse DCF'!$C$15)))+'Reverse DCF'!$C$8*(1+'Reverse DCF'!$C$19)^'Reverse DCF'!$C$15*(1+C$21)/($B26-C$21)/(1+$B26)^'Reverse DCF'!$C$15-'Reverse DCF'!$C$10)/'Reverse DCF'!$C$9,"N/A") | D26: =IFERROR((SUMPRODUCT('Reverse DCF'!$C$8*(1+'Reverse DCF'!$C$19)^ROW(INDIRECT("1:"&'Reverse DCF'!$C$15)),(1/(1+$B26))^ROW(INDIRECT("1:"&'Reverse DCF'!$C$15)))+'Reverse DCF'!$C$8*(1+'Reverse DCF'!$C$19)^'Reverse DCF'!$C$15*(1+D$21)/($B26-D$21)/(1+$B26)^'Reverse DCF'!$C$15-'Reverse DCF'!$C$10)/'Reverse DCF'!$C$9,"N/A") | E26: =IFERROR((SUMPRODUCT('Reverse DCF'!$C$8*(1+'Reverse DCF'!$C$19)^ROW(INDIRECT("1:"&'Reverse DCF'!$C$15)),(1/(1+$B26))^ROW(INDIRECT("1:"&'Reverse DCF'!$C$15)))+'Reverse DCF'!$C$8*(1+'Reverse DCF'!$C$19)^'Reverse DCF'!$C$15*(1+E$21)/($B26-E$21)/(1+$B26)^'Reverse DCF'!$C$15-'Reverse DCF'!$C$10)/'Reverse DCF'!$C$9,"N/A") | F26: =IFERROR((SUMPRODUCT('Reverse DCF'!$C$8*(1+'Reverse DCF'!$C$19)^ROW(INDIRECT("1:"&'Reverse DCF'!$C$15)),(1/(1+$B26))^ROW(INDIRECT("1:"&'Reverse DCF'!$C$15)))+'Reverse DCF'!$C$8*(1+'Reverse DCF'!$C$19)^'Reverse DCF'!$C$15*(1+F$21)/($B26-F$21)/(1+$B26)^'Reverse DCF'!$C$15-'Reverse DCF'!$C$10)/'Reverse DCF'!$C$9,"N/A") | G26: =IFERROR((SUMPRODUCT('Reverse DCF'!$C$8*(1+'Reverse DCF'!$C$19)^ROW(INDIRECT("1:"&'Reverse DCF'!$C$15)),(1/(1+$B26))^ROW(INDIRECT("1:"&'Reverse DCF'!$C$15)))+'Reverse DCF'!$C$8*(1+'Reverse DCF'!$C$19)^'Reverse DCF'!$C$15*(1+G$21)/($B26-G$21)/(1+$B26)^'Reverse DCF'!$C$15-'Reverse DCF'!$C$10)/'Reverse DCF'!$C$9,"N/A") | H26: =IFERROR((SUMPRODUCT('Reverse DCF'!$C$8*(1+'Reverse DCF'!$C$19)^ROW(INDIRECT("1:"&'Reverse DCF'!$C$15)),(1/(1+$B26))^ROW(INDIRECT("1:"&'Reverse DCF'!$C$15)))+'Reverse DCF'!$C$8*(1+'Reverse DCF'!$C$19)^'Reverse DCF'!$C$15*(1+H$21)/($B26-H$21)/(1+$B26)^'Reverse DCF'!$C$15-'Reverse DCF'!$C$10)/'Reverse DCF'!$C$9,"N/A") | I26: =IFERROR((SUMPRODUCT('Reverse DCF'!$C$8*(1+'Reverse DCF'!$C$19)^ROW(INDIRECT("1:"&'Reverse DCF'!$C$15)),(1/(1+$B26))^ROW(INDIRECT("1:"&'Reverse DCF'!$C$15)))+'Reverse DCF'!$C$8*(1+'Reverse DCF'!$C$19)^'Reverse DCF'!$C$15*(1+I$21)/($B26-I$21)/(1+$B26)^'Reverse DCF'!$C$15-'Reverse DCF'!$C$10)/'Reverse DCF'!$C$9,"N/A")
B27: 13% | C27: =IFERROR((SUMPRODUCT('Reverse DCF'!$C$8*(1+'Reverse DCF'!$C$19)^ROW(INDIRECT("1:"&'Reverse DCF'!$C$15)),(1/(1+$B27))^ROW(INDIRECT("1:"&'Reverse DCF'!$C$15)))+'Reverse DCF'!$C$8*(1+'Reverse DCF'!$C$19)^'Reverse DCF'!$C$15*(1+C$21)/($B27-C$21)/(1+$B27)^'Reverse DCF'!$C$15-'Reverse DCF'!$C$10)/'Reverse DCF'!$C$9,"N/A") | D27: =IFERROR((SUMPRODUCT('Reverse DCF'!$C$8*(1+'Reverse DCF'!$C$19)^ROW(INDIRECT("1:"&'Reverse DCF'!$C$15)),(1/(1+$B27))^ROW(INDIRECT("1:"&'Reverse DCF'!$C$15)))+'Reverse DCF'!$C$8*(1+'Reverse DCF'!$C$19)^'Reverse DCF'!$C$15*(1+D$21)/($B27-D$21)/(1+$B27)^'Reverse DCF'!$C$15-'Reverse DCF'!$C$10)/'Reverse DCF'!$C$9,"N/A") | E27: =IFERROR((SUMPRODUCT('Reverse DCF'!$C$8*(1+'Reverse DCF'!$C$19)^ROW(INDIRECT("1:"&'Reverse DCF'!$C$15)),(1/(1+$B27))^ROW(INDIRECT("1:"&'Reverse DCF'!$C$15)))+'Reverse DCF'!$C$8*(1+'Reverse DCF'!$C$19)^'Reverse DCF'!$C$15*(1+E$21)/($B27-E$21)/(1+$B27)^'Reverse DCF'!$C$15-'Reverse DCF'!$C$10)/'Reverse DCF'!$C$9,"N/A") | F27: =IFERROR((SUMPRODUCT('Reverse DCF'!$C$8*(1+'Reverse DCF'!$C$19)^ROW(INDIRECT("1:"&'Reverse DCF'!$C$15)),(1/(1+$B27))^ROW(INDIRECT("1:"&'Reverse DCF'!$C$15)))+'Reverse DCF'!$C$8*(1+'Reverse DCF'!$C$19)^'Reverse DCF'!$C$15*(1+F$21)/($B27-F$21)/(1+$B27)^'Reverse DCF'!$C$15-'Reverse DCF'!$C$10)/'Reverse DCF'!$C$9,"N/A") | G27: =IFERROR((SUMPRODUCT('Reverse DCF'!$C$8*(1+'Reverse DCF'!$C$19)^ROW(INDIRECT("1:"&'Reverse DCF'!$C$15)),(1/(1+$B27))^ROW(INDIRECT("1:"&'Reverse DCF'!$C$15)))+'Reverse DCF'!$C$8*(1+'Reverse DCF'!$C$19)^'Reverse DCF'!$C$15*(1+G$21)/($B27-G$21)/(1+$B27)^'Reverse DCF'!$C$15-'Reverse DCF'!$C$10)/'Reverse DCF'!$C$9,"N/A") | H27: =IFERROR((SUMPRODUCT('Reverse DCF'!$C$8*(1+'Reverse DCF'!$C$19)^ROW(INDIRECT("1:"&'Reverse DCF'!$C$15)),(1/(1+$B27))^ROW(INDIRECT("1:"&'Reverse DCF'!$C$15)))+'Reverse DCF'!$C$8*(1+'Reverse DCF'!$C$19)^'Reverse DCF'!$C$15*(1+H$21)/($B27-H$21)/(1+$B27)^'Reverse DCF'!$C$15-'Reverse DCF'!$C$10)/'Reverse DCF'!$C$9,"N/A") | I27: =IFERROR((SUMPRODUCT('Reverse DCF'!$C$8*(1+'Reverse DCF'!$C$19)^ROW(INDIRECT("1:"&'Reverse DCF'!$C$15)),(1/(1+$B27))^ROW(INDIRECT("1:"&'Reverse DCF'!$C$15)))+'Reverse DCF'!$C$8*(1+'Reverse DCF'!$C$19)^'Reverse DCF'!$C$15*(1+I$21)/($B27-I$21)/(1+$B27)^'Reverse DCF'!$C$15-'Reverse DCF'!$C$10)/'Reverse DCF'!$C$9,"N/A")
B28: 14% | C28: =IFERROR((SUMPRODUCT('Reverse DCF'!$C$8*(1+'Reverse DCF'!$C$19)^ROW(INDIRECT("1:"&'Reverse DCF'!$C$15)),(1/(1+$B28))^ROW(INDIRECT("1:"&'Reverse DCF'!$C$15)))+'Reverse DCF'!$C$8*(1+'Reverse DCF'!$C$19)^'Reverse DCF'!$C$15*(1+C$21)/($B28-C$21)/(1+$B28)^'Reverse DCF'!$C$15-'Reverse DCF'!$C$10)/'Reverse DCF'!$C$9,"N/A") | D28: =IFERROR((SUMPRODUCT('Reverse DCF'!$C$8*(1+'Reverse DCF'!$C$19)^ROW(INDIRECT("1:"&'Reverse DCF'!$C$15)),(1/(1+$B28))^ROW(INDIRECT("1:"&'Reverse DCF'!$C$15)))+'Reverse DCF'!$C$8*(1+'Reverse DCF'!$C$19)^'Reverse DCF'!$C$15*(1+D$21)/($B28-D$21)/(1+$B28)^'Reverse DCF'!$C$15-'Reverse DCF'!$C$10)/'Reverse DCF'!$C$9,"N/A") | E28: =IFERROR((SUMPRODUCT('Reverse DCF'!$C$8*(1+'Reverse DCF'!$C$19)^ROW(INDIRECT("1:"&'Reverse DCF'!$C$15)),(1/(1+$B28))^ROW(INDIRECT("1:"&'Reverse DCF'!$C$15)))+'Reverse DCF'!$C$8*(1+'Reverse DCF'!$C$19)^'Reverse DCF'!$C$15*(1+E$21)/($B28-E$21)/(1+$B28)^'Reverse DCF'!$C$15-'Reverse DCF'!$C$10)/'Reverse DCF'!$C$9,"N/A") | F28: =IFERROR((SUMPRODUCT('Reverse DCF'!$C$8*(1+'Reverse DCF'!$C$19)^ROW(INDIRECT("1:"&'Reverse DCF'!$C$15)),(1/(1+$B28))^ROW(INDIRECT("1:"&'Reverse DCF'!$C$15)))+'Reverse DCF'!$C$8*(1+'Reverse DCF'!$C$19)^'Reverse DCF'!$C$15*(1+F$21)/($B28-F$21)/(1+$B28)^'Reverse DCF'!$C$15-'Reverse DCF'!$C$10)/'Reverse DCF'!$C$9,"N/A") | G28: =IFERROR((SUMPRODUCT('Reverse DCF'!$C$8*(1+'Reverse DCF'!$C$19)^ROW(INDIRECT("1:"&'Reverse DCF'!$C$15)),(1/(1+$B28))^ROW(INDIRECT("1:"&'Reverse DCF'!$C$15)))+'Reverse DCF'!$C$8*(1+'Reverse DCF'!$C$19)^'Reverse DCF'!$C$15*(1+G$21)/($B28-G$21)/(1+$B28)^'Reverse DCF'!$C$15-'Reverse DCF'!$C$10)/'Reverse DCF'!$C$9,"N/A") | H28: =IFERROR((SUMPRODUCT('Reverse DCF'!$C$8*(1+'Reverse DCF'!$C$19)^ROW(INDIRECT("1:"&'Reverse DCF'!$C$15)),(1/(1+$B28))^ROW(INDIRECT("1:"&'Reverse DCF'!$C$15)))+'Reverse DCF'!$C$8*(1+'Reverse DCF'!$C$19)^'Reverse DCF'!$C$15*(1+H$21)/($B28-H$21)/(1+$B28)^'Reverse DCF'!$C$15-'Reverse DCF'!$C$10)/'Reverse DCF'!$C$9,"N/A") | I28: =IFERROR((SUMPRODUCT('Reverse DCF'!$C$8*(1+'Reverse DCF'!$C$19)^ROW(INDIRECT("1:"&'Reverse DCF'!$C$15)),(1/(1+$B28))^ROW(INDIRECT("1:"&'Reverse DCF'!$C$15)))+'Reverse DCF'!$C$8*(1+'Reverse DCF'!$C$19)^'Reverse DCF'!$C$15*(1+I$21)/($B28-I$21)/(1+$B28)^'Reverse DCF'!$C$15-'Reverse DCF'!$C$10)/'Reverse DCF'!$C$9,"N/A")
